Workbook

Sheet Sản phẩm
A1: Mã sản phẩm | B1: Tên sản phẩm | C1: DS - ĐV | D1: OEM - DS - ĐV | E1: MSG - DS - NK - ĐV
A2: 2150294 | B2: Xúc xích Romas Light (50g) 500g | C2: Food Đức Việt | D2: Food Đức Việt | E2: Food Đức Việt
A3: 2150295 | B3: Xúc xích Romas Light (62g) 500g | C3: Food Đức Việt | D3: Food Đức Việt | E3: Food Đức Việt
A4: 2149882 | B4: Chả giò da xốp nhân thịt 300g | C4: Food Đức Việt | D4: Food Đức Việt | E4: Food Đức Việt
A5: 2149883 | B5: Chả giò da xốp hải sản 300g | C5: Food Đức Việt | D5: Food Đức Việt | E5: Food Đức Việt
A6: 1108036 | B6: Rong biển giòn trộn khô gà 100g * 30EA (HD) | C6: Food Daesang | D6: Food Daesang | E6: Food Daesang
A7: 2150337 | B7: O'food chả giò da xốp nhân thịt 300g | C7: Food Đức Việt | D7: Food Đức Việt | E7: Food Đức Việt
A8: 2150338 | B8: O'food chả giò da xốp hải sản 300g | C8: Food Đức Việt | D8: Food Đức Việt | E8: Food Đức Việt
A9: 1108084 | B9: Bánh gạo Hàn Quốc 30g (Micoem) | C9: Food Daesang | D9: Food Daesang | E9: Food Daesang
A10: 2146426 | B10: Bánh bao bò nướng Bulgogi 200g * 20EA | C10: Food Đức Việt | D10: Food Đức Việt | E10: Food Đức Việt
A11: 2146431 | B11: Sủi cảo nhân thịt heo rau củ 450g * 24EA | C11: Food Đức Việt | D11: Food Đức Việt | E11: Food Đức Việt
A12: 1107847 | B12: Tteokbokki Hàn Quốc Mix vị Tân Việt - XK Ba Lan (gói) 140g *32EA | C12: Food Daesang | D12: Food Daesang | E12: Food Daesang
... A982: 2153300 | B982: Tokpokki chả cá 350g | C982: Food Đức Việt | D982: Food Đức Việt | E982: Food Đức Việt

Sheet Giá gốc
A1: Mã Barcode | B1: Mã sản phẩm | C1: Tên sản phẩm | D1: Giá gốc | E1: Hệ thống
A2: 8935304200226 | B2: 1023739 | C2: Lá Kim tẩm dầu Oliu 5g lốc 3 * 36 lốc (HD) | D2: 26095 | E2: Win+
A3: 8935304201810 | B3: 1024697 | C3: Lá Kim Trẻ em 5g lốc 3 * 36 lốc (HD) | D3: 29645 | E3: Win+
A4: 8935304201841 | B4: 1024696 | C4: Lá Kim Tảo biển cao cấp 5g lốc 3 * 36 lốc (HD) | D4: 29645 | E4: Win+
A5: 8935304200769 | B5: 1106055 | C5: Rong biển giòn trộn khô gà 40G KM lá kim tẩm dầu oliu 4G (30 lốc) HD | D5: 29568 | E5: Win+
A6: 8935304200240 | B6: 1106048 | C6: Rong biển giòn trộn gia vị 40g KM lá kim tẩm dầu oliu 4g (30 lốc) HD | D6: 27600 | E6: Win+
A7: 8935304200837 | B7: 1106056 | C7: Rong biển giòn trộn hạt óc chó, hạnh nhân 40G KM lá kim tẩm dầu oliu 4G (30 lốc) HD | D7: 29568 | E7: Win+
A8: 8935304200783 | B8: 1106049 | C8: Rong biển giòn trộn hải sản 40G KM lá kim tẩm dầu oliu 4G (30 lốc) HD | D8: 29568 | E8: Win+
A9: 8935304200219 | B9: 1023643 | C9: Lá Kim tẩm dầu Ô liu 5g lốc 2 (2 tặng 1) * 40 lốc (HD) | D9: 18768 | E9: Win+
A10: 8801052029450 | B10: 2015475 | C10: Lá Kim tẩm dầu Oliu 4.5g lốc 2 (40 lốc) | D10: 19571 | E10: Win+
A11: 8935304200141 | B11: 1021862 | C11: Tokpokki Hàn Quốc vị phô mai (hộp) 105g * 24EA (HD | D11: 24960 | E11: Win+
A12: 8935304200233 | B12: 1021808 | C12: Lá Kim cuốn cơm 10g * 64EA (HD) | D12: 20064 | E12: Win+
A13: 8935304200608 | B13: 1022846 | C13: Tokpokki Hàn Quốc tròn vị phô mai - Không cay (hộp) 105g*24EA(HD) | D13: 24960 | E13: Win+
... A237: 8935101608164 | B237: 2145716 | C237: Viên mực rong biển 300g | D237: 20000 | E237: Toàn bộ

Sheet Chương trình khuyến mãi
A1: STT | B1: Tên chương trình | C1: Hệ thống | D1: Phạm vi | E1: Ngày áp dụng | F1: Ngày kết thúc | G1: Barcode | H1: Mã sản phẩm | I1: Tên sản phẩm | J1: Giá gốc | K1: % Giảm giá | L1: Giá khuyến mại | M1: Chương trình KM | N1: Mã hàng tặng | O1: Tên hàng tặng | P1: Chương trình KAM | Q1: Loại hàng
A2: =ROW()-1 -> 1 | B2: POST 05 - PHÁI ĐẸP TỎA SÁNG | C2: Toàn bộ | D2: Toàn quốc | E2: 18/02/2026 | F2: 18/03/2026 | G2: 8935101600250 | H2: =VLOOKUP(gia_khuyen_mai[[#This Row],[Barcode]],'Giá gốc'!$A:$B,2,0) -> 2145686 | I2: =VLOOKUP(gia_khuyen_mai[[#This Row],[Mã sản phẩm]],'Giá gốc'!$B:$C,2,0) -> Xúc xích hong khói 450g | J2: =VLOOKUP(gia_khuyen_mai[[#This Row],[Mã sản phẩm]],'Giá gốc'!B:D,3,0) -> 79100 | L2: =ROUND((1-gia_khuyen_mai[[#This Row],[% Giảm giá]]) * gia_khuyen_mai[[#This Row],[Giá gốc]], 0) -> 79100 | M2: Mua 1 tặng 1 | N2: 2145765 | O2: =IFERROR(VLOOKUP(gia_khuyen_mai[[#This Row],[Mã hàng tặng]],'Giá gốc'!B:C,2,0),"") -> Xúc xích Hotdog 200g | Q2: =VLOOKUP(gia_khuyen_mai[[#This Row],[Mã sản phẩm]],product[[Mã sản phẩm]:[DS - ĐV]],3,0) -> Food Đức Việt
A3: =ROW()-1 -> 2 | B3: POST 05 - PHÁI ĐẸP TỎA SÁNG | C3: Toàn bộ | D3: Toàn quốc | E3: 18/02/2026 | F3: 18/03/2026 | G3: 8935101608478 | H3: =VLOOKUP(gia_khuyen_mai[[#This Row],[Barcode]],'Giá gốc'!$A:$B,2,0) -> 2150337 | I3: =VLOOKUP(gia_khuyen_mai[[#This Row],[Mã sản phẩm]],'Giá gốc'!$B:$C,2,0) -> O'food Chả giò da xốp nhân thịt 300g | J3: =VLOOKUP(gia_khuyen_mai[[#This Row],[Mã sản phẩm]],'Giá gốc'!B:D,3,0) -> 31524 | K3: 0.3 | L3: =ROUND((1-gia_khuyen_mai[[#This Row],[% Giảm giá]]) * gia_khuyen_mai[[#This Row],[Giá gốc]], 0) -> 22067 | O3: =IFERROR(VLOOKUP(gia_khuyen_mai[[#This Row],[Mã hàng tặng]],'Giá gốc'!B:C,2,0),"") | Q3: =VLOOKUP(gia_khuyen_mai[[#This Row],[Mã sản phẩm]],product[[Mã sản phẩm]:[DS - ĐV]],3,0) -> Food Đức Việt
A4: =ROW()-1 -> 3 | B4: POST 05 - PHÁI ĐẸP TỎA SÁNG | C4: Toàn bộ | D4: Toàn quốc | E4: 18/02/2026 | F4: 17/03/2026 | G4: 8935101608072 | H4: =VLOOKUP(gia_khuyen_mai[[#This Row],[Barcode]],'Giá gốc'!$A:$B,2,0) -> 2145743 | I4: =VLOOKUP(gia_khuyen_mai[[#This Row],[Mã sản phẩm]],'Giá gốc'!$B:$C,2,0) -> Xúc xích sụn nướng Bulgogi 450g | J4: =VLOOKUP(gia_khuyen_mai[[#This Row],[Mã sản phẩm]],'Giá gốc'!B:D,3,0) -> 74500 | K4: 0.3 | L4: =ROUND((1-gia_khuyen_mai[[#This Row],[% Giảm giá]]) * gia_khuyen_mai[[#This Row],[Giá gốc]], 0) -> 52150 | O4: =IFERROR(VLOOKUP(gia_khuyen_mai[[#This Row],[Mã hàng tặng]],'Giá gốc'!B:C,2,0),"") | Q4: =VLOOKUP(gia_khuyen_mai[[#This Row],[Mã sản phẩm]],product[[Mã sản phẩm]:[DS - ĐV]],3,0) -> Food Đức Việt
A5: =ROW()-1 -> 4 | B5: POST 05 - PHÁI ĐẸP TỎA SÁNG | C5: Toàn bộ | D5: Toàn quốc | E5: 18/02/2026 | F5: 18/03/2026 | G5: 8935101607938 | H5: =VLOOKUP(gia_khuyen_mai[[#This Row],[Barcode]],'Giá gốc'!$A:$B,2,0) -> 2145726 | I5: =VLOOKUP(gia_khuyen_mai[[#This Row],[Mã sản phẩm]],'Giá gốc'!$B:$C,2,0) -> Xúc xích phô mai Cheesy 250g | J5: =VLOOKUP(gia_khuyen_mai[[#This Row],[Mã sản phẩm]],'Giá gốc'!B:D,3,0) -> 49400 | K5: 0.3 | L5: =ROUND((1-gia_khuyen_mai[[#This Row],[% Giảm giá]]) * gia_khuyen_mai[[#This Row],[Giá gốc]], 0) -> 34580 | O5: =IFERROR(VLOOKUP(gia_khuyen_mai[[#This Row],[Mã hàng tặng]],'Giá gốc'!B:C,2,0),"") | Q5: =VLOOKUP(gia_khuyen_mai[[#This Row],[Mã sản phẩm]],product[[Mã sản phẩm]:[DS - ĐV]],3,0) -> Food Đức Việt
A6: =ROW()-1 -> 5 | B6: POST 05 - PHÁI ĐẸP TỎA SÁNG | C6: Toàn bộ | D6: Toàn quốc | E6: 18/02/2026 | F6: 18/03/2026 | G6: 8935101608102 | H6: =VLOOKUP(gia_khuyen_mai[[#This Row],[Barcode]],'Giá gốc'!$A:$B,2,0) -> 2145622 | I6: =VLOOKUP(gia_khuyen_mai[[#This Row],[Mã sản phẩm]],'Giá gốc'!$B:$C,2,0) -> Kim chi 450 | J6: =VLOOKUP(gia_khuyen_mai[[#This Row],[Mã sản phẩm]],'Giá gốc'!B:D,3,0) -> 35500 | K6: 0.3 | L6: =ROUND((1-gia_khuyen_mai[[#This Row],[% Giảm giá]]) * gia_khuyen_mai[[#This Row],[Giá gốc]], 0) -> 24850 | O6: =IFERROR(VLOOKUP(gia_khuyen_mai[[#This Row],[Mã hàng tặng]],'Giá gốc'!B:C,2,0),"") | Q6: =VLOOKUP(gia_khuyen_mai[[#This Row],[Mã sản phẩm]],product[[Mã sản phẩm]:[DS - ĐV]],3,0) -> Food Đức Việt
A7: =ROW()-1 -> 6 | B7: POST 05 - PHÁI ĐẸP TỎA SÁNG | C7: Toàn bộ | D7: Toàn quốc | E7: 18/02/2026 | F7: 18/03/2026 | G7: 8935101605118 | H7: =VLOOKUP(gia_khuyen_mai[[#This Row],[Barcode]],'Giá gốc'!$A:$B,2,0) -> 2145783 | I7: =VLOOKUP(gia_khuyen_mai[[#This Row],[Mã sản phẩm]],'Giá gốc'!$B:$C,2,0) -> Xúc xích Romas ( 50g) 500g | J7: =VLOOKUP(gia_khuyen_mai[[#This Row],[Mã sản phẩm]],'Giá gốc'!B:D,3,0) -> 53900 | K7: 0.25 | L7: =ROUND((1-gia_khuyen_mai[[#This Row],[% Giảm giá]]) * gia_khuyen_mai[[#This Row],[Giá gốc]], 0) -> 40425 | O7: =IFERROR(VLOOKUP(gia_khuyen_mai[[#This Row],[Mã hàng tặng]],'Giá gốc'!B:C,2,0),"") | Q7: =VLOOKUP(gia_khuyen_mai[[#This Row],[Mã sản phẩm]],product[[Mã sản phẩm]:[DS - ĐV]],3,0) -> Food Đức Việt
A8: =ROW()-1 -> 7 | B8: POST 05 - PHÁI ĐẸP TỎA SÁNG | C8: Toàn bộ | D8: Toàn quốc | E8: 18/02/2026 | F8: 18/03/2026 | G8: 8935101605989 | H8: =VLOOKUP(gia_khuyen_mai[[#This Row],[Barcode]],'Giá gốc'!$A:$B,2,0) -> 2145774 | I8: =VLOOKUP(gia_khuyen_mai[[#This Row],[Mã sản phẩm]],'Giá gốc'!$B:$C,2,0) -> Xúc xích Pari (50g) 500g | J8: =VLOOKUP(gia_khuyen_mai[[#This Row],[Mã sản phẩm]],'Giá gốc'!B:D,3,0) -> 55600 | K8: 0.22 | L8: =ROUND((1-gia_khuyen_mai[[#This Row],[% Giảm giá]]) * gia_khuyen_mai[[#This Row],[Giá gốc]], 0) -> 43368 | O8: =IFERROR(VLOOKUP(gia_khuyen_mai[[#This Row],[Mã hàng tặng]],'Giá gốc'!B:C,2,0),"") | Q8: =VLOOKUP(gia_khuyen_mai[[#This Row],[Mã sản phẩm]],product[[Mã sản phẩm]:[DS - ĐV]],3,0) -> Food Đức Việt
A9: =ROW()-1 -> 8 | B9: Post Aging | C9: Win+ | D9: Toàn quốc | E9: 18/02/2026 | F9: 27/02/2026 | G9: 8935101600427 | H9: =VLOOKUP(gia_khuyen_mai[[#This Row],[Barcode]],'Giá gốc'!$A:$B,2,0) -> 2145691 | I9: =VLOOKUP(gia_khuyen_mai[[#This Row],[Mã sản phẩm]],'Giá gốc'!$B:$C,2,0) -> Xúc xích viên hong khói 450g * 1EA | J9: =VLOOKUP(gia_khuyen_mai[[#This Row],[Mã sản phẩm]],'Giá gốc'!B:D,3,0) -> 84200 | L9: =ROUND((1-gia_khuyen_mai[[#This Row],[% Giảm giá]]) * gia_khuyen_mai[[#This Row],[Giá gốc]], 0) -> 84200 | M9: Mua 1 tặng 1 | N9: 2145740 | O9: =IFERROR(VLOOKUP(gia_khuyen_mai[[#This Row],[Mã hàng tặng]],'Giá gốc'!B:C,2,0),"") -> Xúc xích phô mai Cheesy 70g * 30EA | Q9: =VLOOKUP(gia_khuyen_mai[[#This Row],[Mã sản phẩm]],product[[Mã sản phẩm]:[DS - ĐV]],3,0) -> Food Đức Việt
A10: =ROW()-1 -> 9 | B10: POST 06 - Bếp vui, Giá tốt mỗi ngày | C10: Toàn bộ | D10: Toàn quốc | E10: 05/03/2026 | F10: 31/03/2026 | G10: 8935101608348 | H10: =VLOOKUP(gia_khuyen_mai[[#This Row],[Barcode]],'Giá gốc'!$A:$B,2,0) -> 2145744 | I10: =VLOOKUP(gia_khuyen_mai[[#This Row],[Mã sản phẩm]],'Giá gốc'!$B:$C,2,0) -> Xúc xích bắp phô mai 250g | J10: =VLOOKUP(gia_khuyen_mai[[#This Row],[Mã sản phẩm]],'Giá gốc'!B:D,3,0) -> 49400 | K10: 0.3 | L10: =ROUND((1-gia_khuyen_mai[[#This Row],[% Giảm giá]]) * gia_khuyen_mai[[#This Row],[Giá gốc]], 0) -> 34580 | O10: =IFERROR(VLOOKUP(gia_khuyen_mai[[#This Row],[Mã hàng tặng]],'Giá gốc'!B:C,2,0),"") | Q10: =VLOOKUP(gia_khuyen_mai[[#This Row],[Mã sản phẩm]],product[[Mã sản phẩm]:[DS - ĐV]],3,0) -> Food Đức Việt
A11: =ROW()-1 -> 10 | B11: POST 06 - Bếp vui, Giá tốt mỗi ngày | C11: Toàn bộ | D11: Toàn quốc | E11: 05/03/2026 | F11: 01/04/2026 | G11: 8935101607877 | H11: =VLOOKUP(gia_khuyen_mai[[#This Row],[Barcode]],'Giá gốc'!$A:$B,2,0) -> 2145699 | I11: =VLOOKUP(gia_khuyen_mai[[#This Row],[Mã sản phẩm]],'Giá gốc'!$B:$C,2,0) -> Seoul's Hotdog Chiên xù 250g (Đ) | J11: =VLOOKUP(gia_khuyen_mai[[#This Row],[Mã sản phẩm]],'Giá gốc'!B:D,3,0) -> 39150 | K11: 0.22 | L11: =ROUND((1-gia_khuyen_mai[[#This Row],[% Giảm giá]]) * gia_khuyen_mai[[#This Row],[Giá gốc]], 0) -> 30537 | O11: =IFERROR(VLOOKUP(gia_khuyen_mai[[#This Row],[Mã hàng tặng]],'Giá gốc'!B:C,2,0),"") | Q11: =VLOOKUP(gia_khuyen_mai[[#This Row],[Mã sản phẩm]],product[[Mã sản phẩm]:[DS - ĐV]],3,0) -> Food Đức Việt
A12: =ROW()-1 -> 11 | B12: POST 06 - Bếp vui, Giá tốt mỗi ngày | C12: Toàn bộ | D12: Toàn quốc | E12: 05/03/2026 | F12: 31/03/2026 | G12: 8935101600960 | H12: =VLOOKUP(gia_khuyen_mai[[#This Row],[Barcode]],'Giá gốc'!$A:$B,2,0) -> 2145745 | I12: =VLOOKUP(gia_khuyen_mai[[#This Row],[Mã sản phẩm]],'Giá gốc'!$B:$C,2,0) -> Jăm bông hấp 200g | J12: =VLOOKUP(gia_khuyen_mai[[#This Row],[Mã sản phẩm]],'Giá gốc'!B:D,3,0) -> 37000 | K12: 0.15 | L12: =ROUND((1-gia_khuyen_mai[[#This Row],[% Giảm giá]]) * gia_khuyen_mai[[#This Row],[Giá gốc]], 0) -> 31450 | O12: =IFERROR(VLOOKUP(gia_khuyen_mai[[#This Row],[Mã hàng tặng]],'Giá gốc'!B:C,2,0),"") | Q12: =VLOOKUP(gia_khuyen_mai[[#This Row],[Mã sản phẩm]],product[[Mã sản phẩm]:[DS - ĐV]],3,0) -> Food Đức Việt
A13: =ROW()-1 -> 12 | B13: POST 06 - Bếp vui, Giá tốt mỗi ngày | C13: Toàn bộ | D13: Toàn quốc | E13: 05/03/2026 | F13: 01/04/2026 | G13: 8935101604883 | H13: =VLOOKUP(gia_khuyen_mai[[#This Row],[Barcode]],'Giá gốc'!$A:$B,2,0) -> 2145765 | I13: =VLOOKUP(gia_khuyen_mai[[#This Row],[Mã sản phẩm]],'Giá gốc'!$B:$C,2,0) -> Xúc xích Hotdog 200g | J13: =VLOOKUP(gia_khuyen_mai[[#This Row],[Mã sản phẩm]],'Giá gốc'!B:D,3,0) -> 20100 | K13: 0.2 | L13: =ROUND((1-gia_khuyen_mai[[#This Row],[% Giảm giá]]) * gia_khuyen_mai[[#This Row],[Giá gốc]], 0) -> 16080 | O13: =IFERROR(VLOOKUP(gia_khuyen_mai[[#This Row],[Mã hàng tặng]],'Giá gốc'!B:C,2,0),"") | Q13: =VLOOKUP(gia_khuyen_mai[[#This Row],[Mã sản phẩm]],product[[Mã sản phẩm]:[DS - ĐV]],3,0) -> Food Đức Việt
A14: =ROW()-1 -> 13 | B14: POST 06 - Bếp vui, Giá tốt mỗi ngày | C14: Toàn bộ | D14: Toàn quốc | E14: 05/03/2026 | F14: 01/04/2026 | G14: 8935101600380 | H14: =VLOOKUP(gia_khuyen_mai[[#This Row],[Barcode]],'Giá gốc'!$A:$B,2,0) -> 2145690 | I14: =VLOOKUP(gia_khuyen_mai[[#This Row],[Mã sản phẩm]],'Giá gốc'!$B:$C,2,0) -> Xúc xích vườn bia 200g * 1EA | J14: =VLOOKUP(gia_khuyen_mai[[#This Row],[Mã sản phẩm]],'Giá gốc'!B:D,3,0) -> 38400 | K14: 0.2 | L14: =ROUND((1-gia_khuyen_mai[[#This Row],[% Giảm giá]]) * gia_khuyen_mai[[#This Row],[Giá gốc]], 0) -> 30720 | O14: =IFERROR(VLOOKUP(gia_khuyen_mai[[#This Row],[Mã hàng tặng]],'Giá gốc'!B:C,2,0),"") | Q14: =VLOOKUP(gia_khuyen_mai[[#This Row],[Mã sản phẩm]],product[[Mã sản phẩm]:[DS - ĐV]],3,0) -> Food Đức Việt
A15: =ROW()-1 -> 14 | B15: POST 06 - Bếp vui, Giá tốt mỗi ngày | C15: Toàn bộ | D15: Toàn quốc | E15: 05/03/2026 | F15: 01/04/2026 | G15: 8935101604913 | H15: =VLOOKUP(gia_khuyen_mai[[#This Row],[Barcode]],'Giá gốc'!$A:$B,2,0) -> 2145762 | I15: =VLOOKUP(gia_khuyen_mai[[#This Row],[Mã sản phẩm]],'Giá gốc'!$B:$C,2,0) -> Xúc xích Cocktail 200g | J15: =VLOOKUP(gia_khuyen_mai[[#This Row],[Mã sản phẩm]],'Giá gốc'!B:D,3,0) -> 21100 | K15: 0.2 | L15: =ROUND((1-gia_khuyen_mai[[#This Row],[% Giảm giá]]) * gia_khuyen_mai[[#This Row],[Giá gốc]], 0) -> 16880 | O15: =IFERROR(VLOOKUP(gia_khuyen_mai[[#This Row],[Mã hàng tặng]],'Giá gốc'!B:C,2,0),"") | Q15: =VLOOKUP(gia_khuyen_mai[[#This Row],[Mã sản phẩm]],product[[Mã sản phẩm]:[DS - ĐV]],3,0) -> Food Đức Việt
A16: =ROW()-1 -> 15 | B16: POST 06 - Bếp vui, Giá tốt mỗi ngày | C16: Toàn bộ | D16: Toàn quốc | E16: 05/03/2026 | F16: 31/03/2026 | G16: 8935101608461 | H16: =VLOOKUP(gia_khuyen_mai[[#This Row],[Barcode]],'Giá gốc'!$A:$B,2,0) -> 2150338 | I16: =VLOOKUP(gia_khuyen_mai[[#This Row],[Mã sản phẩm]],'Giá gốc'!$B:$C,2,0) -> O'food Chả giò da xốp hải sản 300g | J16: =VLOOKUP(gia_khuyen_mai[[#This Row],[Mã sản phẩm]],'Giá gốc'!B:D,3,0) -> 31524 | K16: 0.3 | L16: =ROUND((1-gia_khuyen_mai[[#This Row],[% Giảm giá]]) * gia_khuyen_mai[[#This Row],[Giá gốc]], 0) -> 22067 | O16: =IFERROR(VLOOKUP(gia_khuyen_mai[[#This Row],[Mã hàng tặng]],'Giá gốc'!B:C,2,0),"") | Q16: =VLOOKUP(gia_khuyen_mai[[#This Row],[Mã sản phẩm]],product[[Mã sản phẩm]:[DS - ĐV]],3,0) -> Food Đức Việt
A17: =ROW()-1 -> 16 | B17: POST 06 - Bếp vui, Giá tốt mỗi ngày | C17: Toàn bộ | D17: Toàn quốc | E17: 05/03/2026 | F17: 01/04/2026 | G17: 8935101600427 | H17: =VLOOKUP(gia_khuyen_mai[[#This Row],[Barcode]],'Giá gốc'!$A:$B,2,0) -> 2145691 | I17: =VLOOKUP(gia_khuyen_mai[[#This Row],[Mã sản phẩm]],'Giá gốc'!$B:$C,2,0) -> Xúc xích viên hong khói 450g * 1EA | J17: =VLOOKUP(gia_khuyen_mai[[#This Row],[Mã sản phẩm]],'Giá gốc'!B:D,3,0) -> 84200 | L17: =ROUND((1-gia_khuyen_mai[[#This Row],[% Giảm giá]]) * gia_khuyen_mai[[#This Row],[Giá gốc]], 0) -> 84200 | M17: Mua 1 tặng 1 | N17: 2145765 | O17: =IFERROR(VLOOKUP(gia_khuyen_mai[[#This Row],[Mã hàng tặng]],'Giá gốc'!B:C,2,0),"") -> Xúc xích Hotdog 200g | Q17: =VLOOKUP(gia_khuyen_mai[[#This Row],[Mã sản phẩm]],product[[Mã sản phẩm]:[DS - ĐV]],3,0) -> Food Đức Việt
A18: =ROW()-1 -> 17 | B18: POST 07 | C18: Toàn bộ | D18: Toàn quốc | E18: 18/03/2026 | F18: 15/04/2026 | G18: 8935101600625 | H18: =VLOOKUP(gia_khuyen_mai[[#This Row],[Barcode]],'Giá gốc'!$A:$B,2,0) -> 2145689 | I18: =VLOOKUP(gia_khuyen_mai[[#This Row],[Mã sản phẩm]],'Giá gốc'!$B:$C,2,0) -> Xúc xích vườn bia 450g * 1EA | J18: =VLOOKUP(gia_khuyen_mai[[#This Row],[Mã sản phẩm]],'Giá gốc'!B:D,3,0) -> 84200 | L18: =ROUND((1-gia_khuyen_mai[[#This Row],[% Giảm giá]]) * gia_khuyen_mai[[#This Row],[Giá gốc]], 0) -> 84200 | M18: Mua 1 tặng 1 | N18: 2145765 | O18: =IFERROR(VLOOKUP(gia_khuyen_mai[[#This Row],[Mã hàng tặng]],'Giá gốc'!B:C,2,0),"") -> Xúc xích Hotdog 200g | Q18: =VLOOKUP(gia_khuyen_mai[[#This Row],[Mã sản phẩm]],product[[Mã sản phẩm]:[DS - ĐV]],3,0) -> Food Đức Việt
A19: =ROW()-1 -> 18 | B19: POST 07 | C19: Toàn bộ | D19: Toàn quốc | E19: 18/03/2026 | F19: 15/04/2026 | G19: 8935101608072 | H19: =VLOOKUP(gia_khuyen_mai[[#This Row],[Barcode]],'Giá gốc'!$A:$B,2,0) -> 2145743 | I19: =VLOOKUP(gia_khuyen_mai[[#This Row],[Mã sản phẩm]],'Giá gốc'!$B:$C,2,0) -> Xúc xích sụn nướng Bulgogi 450g | J19: =VLOOKUP(gia_khuyen_mai[[#This Row],[Mã sản phẩm]],'Giá gốc'!B:D,3,0) -> 74500 | K19: 0.3 | L19: =ROUND((1-gia_khuyen_mai[[#This Row],[% Giảm giá]]) * gia_khuyen_mai[[#This Row],[Giá gốc]], 0) -> 52150 | O19: =IFERROR(VLOOKUP(gia_khuyen_mai[[#This Row],[Mã hàng tặng]],'Giá gốc'!B:C,2,0),"") | Q19: =VLOOKUP(gia_khuyen_mai[[#This Row],[Mã sản phẩm]],product[[Mã sản phẩm]:[DS - ĐV]],3,0) -> Food Đức Việt
A20: =ROW()-1 -> 19 | B20: POST 07 | C20: Toàn bộ | D20: Toàn quốc | E20: 18/03/2026 | F20: 15/04/2026 | G20: 8935101600366 | H20: =VLOOKUP(gia_khuyen_mai[[#This Row],[Barcode]],'Giá gốc'!$A:$B,2,0) -> 2145688 | I20: =VLOOKUP(gia_khuyen_mai[[#This Row],[Mã sản phẩm]],'Giá gốc'!$B:$C,2,0) -> Xúc xích hong khói 200g * 1EA | J20: =VLOOKUP(gia_khuyen_mai[[#This Row],[Mã sản phẩm]],'Giá gốc'!B:D,3,0) -> 35200 | K20: 0.2 | L20: =ROUND((1-gia_khuyen_mai[[#This Row],[% Giảm giá]]) * gia_khuyen_mai[[#This Row],[Giá gốc]], 0) -> 28160 | O20: =IFERROR(VLOOKUP(gia_khuyen_mai[[#This Row],[Mã hàng tặng]],'Giá gốc'!B:C,2,0),"") | Q20: =VLOOKUP(gia_khuyen_mai[[#This Row],[Mã sản phẩm]],product[[Mã sản phẩm]:[DS - ĐV]],3,0) -> Food Đức Việt
A21: =ROW()-1 -> 20 | B21: POST 07 | C21: Toàn bộ | D21: Toàn quốc | E21: 18/03/2026 | F21: 15/04/2026 | G21: 8935101607105 | H21: =VLOOKUP(gia_khuyen_mai[[#This Row],[Barcode]],'Giá gốc'!$A:$B,2,0) -> 2145648 | I21: =VLOOKUP(gia_khuyen_mai[[#This Row],[Mã sản phẩm]],'Giá gốc'!$B:$C,2,0) -> Đức Việt Handy - xúc xích ăn liền vị heo 105g * 20EA | J21: =VLOOKUP(gia_khuyen_mai[[#This Row],[Mã sản phẩm]],'Giá gốc'!B:D,3,0) -> 9300 | K21: 0.22 | L21: =ROUND((1-gia_khuyen_mai[[#This Row],[% Giảm giá]]) * gia_khuyen_mai[[#This Row],[Giá gốc]], 0) -> 7254 | O21: =IFERROR(VLOOKUP(gia_khuyen_mai[[#This Row],[Mã hàng tặng]],'Giá gốc'!B:C,2,0),"") | Q21: =VLOOKUP(gia_khuyen_mai[[#This Row],[Mã sản phẩm]],product[[Mã sản phẩm]:[DS - ĐV]],3,0) -> Food Đức Việt
A22: =ROW()-1 -> 21 | B22: POST 07 | C22: Toàn bộ | D22: Toàn quốc | E22: 18/03/2026 | F22: 15/04/2026 | G22: 8935101607129 | H22: =VLOOKUP(gia_khuyen_mai[[#This Row],[Barcode]],'Giá gốc'!$A:$B,2,0) -> 2145657 | I22: =VLOOKUP(gia_khuyen_mai[[#This Row],[Mã sản phẩm]],'Giá gốc'!$B:$C,2,0) -> Đức Việt Handy - xúc xích ăn liền vị bò 105g * 20EA | J22: =VLOOKUP(gia_khuyen_mai[[#This Row],[Mã sản phẩm]],'Giá gốc'!B:D,3,0) -> 9300 | K22: 0.22 | L22: =ROUND((1-gia_khuyen_mai[[#This Row],[% Giảm giá]]) * gia_khuyen_mai[[#This Row],[Giá gốc]], 0) -> 7254 | O22: =IFERROR(VLOOKUP(gia_khuyen_mai[[#This Row],[Mã hàng tặng]],'Giá gốc'!B:C,2,0),"") | Q22: =VLOOKUP(gia_khuyen_mai[[#This Row],[Mã sản phẩm]],product[[Mã sản phẩm]:[DS - ĐV]],3,0) -> Food Đức Việt
A23: =ROW()-1 -> 22 | B23: POST 07 | C23: Toàn bộ | D23: Toàn quốc | E23: 18/03/2026 | F23: 15/04/2026 | G23: 8935101601028 | H23: =VLOOKUP(gia_khuyen_mai[[#This Row],[Barcode]],'Giá gốc'!$A:$B,2,0) -> 2145735 | I23: =VLOOKUP(gia_khuyen_mai[[#This Row],[Mã sản phẩm]],'Giá gốc'!$B:$C,2,0) -> Xúc xích tỏi 200g | J23: =VLOOKUP(gia_khuyen_mai[[#This Row],[Mã sản phẩm]],'Giá gốc'!B:D,3,0) -> 37000 | K23: 0.15 | L23: =ROUND((1-gia_khuyen_mai[[#This Row],[% Giảm giá]]) * gia_khuyen_mai[[#This Row],[Giá gốc]], 0) -> 31450 | O23: =IFERROR(VLOOKUP(gia_khuyen_mai[[#This Row],[Mã hàng tặng]],'Giá gốc'!B:C,2,0),"") | Q23: =VLOOKUP(gia_khuyen_mai[[#This Row],[Mã sản phẩm]],product[[Mã sản phẩm]:[DS - ĐV]],3,0) -> Food Đức Việt
A24: =ROW()-1 -> 23 | B24: POST 07 | C24: Toàn bộ | D24: Toàn quốc | E24: 18/03/2026 | F24: 15/04/2026 | G24: 8935101606078 | H24: =VLOOKUP(gia_khuyen_mai[[#This Row],[Barcode]],'Giá gốc'!$A:$B,2,0) -> 2145695 | I24: =VLOOKUP(gia_khuyen_mai[[#This Row],[Mã sản phẩm]],'Giá gốc'!$B:$C,2,0) -> Seoul's Hotdog 350g | J24: =VLOOKUP(gia_khuyen_mai[[#This Row],[Mã sản phẩm]],'Giá gốc'!B:D,3,0) -> 48384 | K24: 0.25 | L24: =ROUND((1-gia_khuyen_mai[[#This Row],[% Giảm giá]]) * gia_khuyen_mai[[#This Row],[Giá gốc]], 0) -> 36288 | O24: =IFERROR(VLOOKUP(gia_khuyen_mai[[#This Row],[Mã hàng tặng]],'Giá gốc'!B:C,2,0),"") | Q24: =VLOOKUP(gia_khuyen_mai[[#This Row],[Mã sản phẩm]],product[[Mã sản phẩm]:[DS - ĐV]],3,0) -> Food Đức Việt
A25: =ROW()-1 -> 24 | B25: POST 07 | C25: Toàn bộ | D25: Toàn quốc | E25: 18/03/2026 | F25: 15/04/2026 | G25: 8935101607099 | H25: =VLOOKUP(gia_khuyen_mai[[#This Row],[Barcode]],'Giá gốc'!$A:$B,2,0) -> 2145697 | I25: =VLOOKUP(gia_khuyen_mai[[#This Row],[Mã sản phẩm]],'Giá gốc'!$B:$C,2,0) -> Seoul nhân phô mai 250g | J25: =VLOOKUP(gia_khuyen_mai[[#This Row],[Mã sản phẩm]],'Giá gốc'!B:D,3,0) -> 42000 | K25: 0.25 | L25: =ROUND((1-gia_khuyen_mai[[#This Row],[% Giảm giá]]) * gia_khuyen_mai[[#This Row],[Giá gốc]], 0) -> 31500 | O25: =IFERROR(VLOOKUP(gia_khuyen_mai[[#This Row],[Mã hàng tặng]],'Giá gốc'!B:C,2,0),"") | Q25: =VLOOKUP(gia_khuyen_mai[[#This Row],[Mã sản phẩm]],product[[Mã sản phẩm]:[DS - ĐV]],3,0) -> Food Đức Việt
A26: =ROW()-1 -> 25 | B26: POST 07 | C26: Toàn bộ | D26: Toàn quốc | E26: 18/03/2026 | F26: 15/04/2026 | G26: 8935101607952 | H26: =VLOOKUP(gia_khuyen_mai[[#This Row],[Barcode]],'Giá gốc'!$A:$B,2,0) -> 2145740 | I26: =VLOOKUP(gia_khuyen_mai[[#This Row],[Mã sản phẩm]],'Giá gốc'!$B:$C,2,0) -> Xúc xích phô mai Cheesy 70g * 30EA | J26: =VLOOKUP(gia_khuyen_mai[[#This Row],[Mã sản phẩm]],'Giá gốc'!B:D,3,0) -> 17100 | K26: 0.2 | L26: =ROUND((1-gia_khuyen_mai[[#This Row],[% Giảm giá]]) * gia_khuyen_mai[[#This Row],[Giá gốc]], 0) -> 13680 | O26: =IFERROR(VLOOKUP(gia_khuyen_mai[[#This Row],[Mã hàng tặng]],'Giá gốc'!B:C,2,0),"") | Q26: =VLOOKUP(gia_khuyen_mai[[#This Row],[Mã sản phẩm]],product[[Mã sản phẩm]:[DS - ĐV]],3,0) -> Food Đức Việt
A27: =ROW()-1 -> 26 | B27: POST 07 | C27: Toàn bộ | D27: Toàn quốc | E27: 18/03/2026 | F27: 15/04/2026 | G27: 8935101607969 | H27: =VLOOKUP(gia_khuyen_mai[[#This Row],[Barcode]],'Giá gốc'!$A:$B,2,0) -> 2145791 | I27: =VLOOKUP(gia_khuyen_mai[[#This Row],[Mã sản phẩm]],'Giá gốc'!$B:$C,2,0) -> Xúc xích Romas 70g * 30EA | J27: =VLOOKUP(gia_khuyen_mai[[#This Row],[Mã sản phẩm]],'Giá gốc'!B:D,3,0) -> 13100 | K27: 0.2 | L27: =ROUND((1-gia_khuyen_mai[[#This Row],[% Giảm giá]]) * gia_khuyen_mai[[#This Row],[Giá gốc]], 0) -> 10480 | O27: =IFERROR(VLOOKUP(gia_khuyen_mai[[#This Row],[Mã hàng tặng]],'Giá gốc'!B:C,2,0),"") | Q27: =VLOOKUP(gia_khuyen_mai[[#This Row],[Mã sản phẩm]],product[[Mã sản phẩm]:[DS - ĐV]],3,0) -> Food Đức Việt
A28: =ROW()-1 -> 27 | B28: POST 07 | C28: Toàn bộ | D28: Toàn quốc | E28: 18/03/2026 | F28: 15/04/2026 | G28: 8935101605804 | H28: =VLOOKUP(gia_khuyen_mai[[#This Row],[Barcode]],'Giá gốc'!$A:$B,2,0) -> 2145767 | I28: =VLOOKUP(gia_khuyen_mai[[#This Row],[Mã sản phẩm]],'Giá gốc'!$B:$C,2,0) -> Xúc xích Mỹ 500g | J28: =VLOOKUP(gia_khuyen_mai[[#This Row],[Mã sản phẩm]],'Giá gốc'!B:D,3,0) -> 55600 | K28: 0.22 | L28: =ROUND((1-gia_khuyen_mai[[#This Row],[% Giảm giá]]) * gia_khuyen_mai[[#This Row],[Giá gốc]], 0) -> 43368 | O28: =IFERROR(VLOOKUP(gia_khuyen_mai[[#This Row],[Mã hàng tặng]],'Giá gốc'!B:C,2,0),"") | Q28: =VLOOKUP(gia_khuyen_mai[[#This Row],[Mã sản phẩm]],product[[Mã sản phẩm]:[DS - ĐV]],3,0) -> Food Đức Việt
A29: =ROW()-1 -> 28 | B29: POST 08 | C29: Toàn bộ | D29: Toàn quốc | E29: 01/04/2026 | F29: 03/05/2026 | G29: 8935101604180 | H29: =VLOOKUP(gia_khuyen_mai[[#This Row],[Barcode]],'Giá gốc'!$A:$B,2,0) -> 2146417 | I29: =VLOOKUP(gia_khuyen_mai[[#This Row],[Mã sản phẩm]],'Giá gốc'!$B:$C,2,0) -> Chân giò hong khói rút xương 300g | J29: =VLOOKUP(gia_khuyen_mai[[#This Row],[Mã sản phẩm]],'Giá gốc'!B:D,3,0) -> 67700 | K29: 0.2 | L29: =ROUND((1-gia_khuyen_mai[[#This Row],[% Giảm giá]]) * gia_khuyen_mai[[#This Row],[Giá gốc]], 0) -> 54160 | O29: =IFERROR(VLOOKUP(gia_khuyen_mai[[#This Row],[Mã hàng tặng]],'Giá gốc'!B:C,2,0),"") | Q29: =VLOOKUP(gia_khuyen_mai[[#This Row],[Mã sản phẩm]],product[[Mã sản phẩm]:[DS - ĐV]],3,0) -> Food Đức Việt
A30: =ROW()-1 -> 29 | B30: POST 08 | C30: Toàn bộ | D30: Toàn quốc | E30: 01/04/2026 | F30: 03/05/2026 | G30: 8935101600960 | H30: =VLOOKUP(gia_khuyen_mai[[#This Row],[Barcode]],'Giá gốc'!$A:$B,2,0) -> 2145745 | I30: =VLOOKUP(gia_khuyen_mai[[#This Row],[Mã sản phẩm]],'Giá gốc'!$B:$C,2,0) -> Jăm bông hấp 200g | J30: =VLOOKUP(gia_khuyen_mai[[#This Row],[Mã sản phẩm]],'Giá gốc'!B:D,3,0) -> 37000 | K30: 0.15 | L30: =ROUND((1-gia_khuyen_mai[[#This Row],[% Giảm giá]]) * gia_khuyen_mai[[#This Row],[Giá gốc]], 0) -> 31450 | O30: =IFERROR(VLOOKUP(gia_khuyen_mai[[#This Row],[Mã hàng tặng]],'Giá gốc'!B:C,2,0),"") | Q30: =VLOOKUP(gia_khuyen_mai[[#This Row],[Mã sản phẩm]],product[[Mã sản phẩm]:[DS - ĐV]],3,0) -> Food Đức Việt
... A48: =ROW()-1 -> 47 | B48: Mã mới | C48: Winmart | D48: Toàn quốc | E48: 09/04/2026 | F48: 13/05/2026 | G48: 8935101608126 | H48: =VLOOKUP(gia_khuyen_mai[[#This Row],[Barcode]],'Giá gốc'!$A:$B,2,0) -> 2145625 | I48: =VLOOKUP(gia_khuyen_mai[[#This Row],[Mã sản phẩm]],'Giá gốc'!$B:$C,2,0) -> Jongga Kim chi cải thảo cắt lát 1kg | J48: =VLOOKUP(gia_khuyen_mai[[#This Row],[Mã sản phẩm]],'Giá gốc'!B:D,3,0) -> 70000 | K48: 0.33 | L48: =ROUND((1-gia_khuyen_mai[[#This Row],[% Giảm giá]]) * gia_khuyen_mai[[#This Row],[Giá gốc]], 0) -> 46900 | O48: =IFERROR(VLOOKUP(gia_khuyen_mai[[#This Row],[Mã hàng tặng]],'Giá gốc'!B:C,2,0),"") | Q48: =VLOOKUP(gia_khuyen_mai[[#This Row],[Mã sản phẩm]],product[[Mã sản phẩm]:[DS - ĐV]],3,0) -> Food Đức Việt
A49: =ROW()-1 -> 48 | B49: Mã mới | C49: Winmart | D49: Toàn quốc | E49: 09/04/2026 | F49: 13/05/2026 | G49: 8935101608515 | H49: =VLOOKUP(gia_khuyen_mai[[#This Row],[Barcode]],'Giá gốc'!$A:$B,2,0) -> 2151032 | I49: =VLOOKUP(gia_khuyen_mai[[#This Row],[Mã sản phẩm]],'Giá gốc'!$B:$C,2,0) -> Jongga Kim chi Củ cải 450g | J49: =VLOOKUP(gia_khuyen_mai[[#This Row],[Mã sản phẩm]],'Giá gốc'!B:D,3,0) -> 42000 | L49: =ROUND((1-gia_khuyen_mai[[#This Row],[% Giảm giá]]) * gia_khuyen_mai[[#This Row],[Giá gốc]], 0) -> 42000 | M49: Mua 1 tặng 1 | N49: =VLOOKUP(gia_khuyen_mai[[#This Row],[Barcode]],'Giá gốc'!$A:$B,2,0) -> 2151032 | O49: =IFERROR(VLOOKUP(gia_khuyen_mai[[#This Row],[Mã hàng tặng]],'Giá gốc'!B:C,2,0),"") -> Jongga Kim chi Củ cải 450g | Q49: =VLOOKUP(gia_khuyen_mai[[#This Row],[Mã sản phẩm]],product[[Mã sản phẩm]:[DS - ĐV]],3,0) -> Food Đức Việt
A50: =ROW()-1 -> 49 | B50: Mã mới | C50: Winmart | D50: Toàn quốc | E50: 09/04/2026 | F50: 13/05/2026 | G50: 8935101608522 | H50: =VLOOKUP(gia_khuyen_mai[[#This Row],[Barcode]],'Giá gốc'!$A:$B,2,0) -> 2151140 | I50: =VLOOKUP(gia_khuyen_mai[[#This Row],[Mã sản phẩm]],'Giá gốc'!$B:$C,2,0) -> Jongga Kim chi Củ cải 150g | J50: =VLOOKUP(gia_khuyen_mai[[#This Row],[Mã sản phẩm]],'Giá gốc'!B:D,3,0) -> 16500 | K50: 0.33 | L50: =ROUND((1-gia_khuyen_mai[[#This Row],[% Giảm giá]]) * gia_khuyen_mai[[#This Row],[Giá gốc]], 0) -> 11055 | O50: =IFERROR(VLOOKUP(gia_khuyen_mai[[#This Row],[Mã hàng tặng]],'Giá gốc'!B:C,2,0),"") | Q50: =VLOOKUP(gia_khuyen_mai[[#This Row],[Mã sản phẩm]],product[[Mã sản phẩm]:[DS - ĐV]],3,0) -> Food Đức Việt
A51: =ROW()-1 -> 50 | B51: Mã mới | C51: Winmart | D51: Toàn quốc | E51: 09/04/2026 | F51: 13/05/2026 | G51: 8935101608546 | H51: =VLOOKUP(gia_khuyen_mai[[#This Row],[Barcode]],'Giá gốc'!$A:$B,2,0) -> 2151765 | I51: =VLOOKUP(gia_khuyen_mai[[#This Row],[Mã sản phẩm]],'Giá gốc'!$B:$C,2,0) -> Ức gà hong khói 100g | J51: =VLOOKUP(gia_khuyen_mai[[#This Row],[Mã sản phẩm]],'Giá gốc'!B:D,3,0) -> 26000 | K51: 0.25 | L51: =ROUND((1-gia_khuyen_mai[[#This Row],[% Giảm giá]]) * gia_khuyen_mai[[#This Row],[Giá gốc]], 0) -> 19500 | O51: =IFERROR(VLOOKUP(gia_khuyen_mai[[#This Row],[Mã hàng tặng]],'Giá gốc'!B:C,2,0),"") | Q51: =VLOOKUP(gia_khuyen_mai[[#This Row],[Mã sản phẩm]],product[[Mã sản phẩm]:[DS - ĐV]],3,0) -> Food Đức Việt
A52: =ROW()-1 -> 51 | B52: Mã mới | C52: Winmart | D52: Toàn quốc | E52: 09/04/2026 | F52: 13/05/2026 | G52: 8935101607945 | H52: =VLOOKUP(gia_khuyen_mai[[#This Row],[Barcode]],'Giá gốc'!$A:$B,2,0) -> 2145747 | I52: =VLOOKUP(gia_khuyen_mai[[#This Row],[Mã sản phẩm]],'Giá gốc'!$B:$C,2,0) -> Xúc xích thịt heo Bragenwurst 400g | J52: =VLOOKUP(gia_khuyen_mai[[#This Row],[Mã sản phẩm]],'Giá gốc'!B:D,3,0) -> 82080 | K52: 0.3 | L52: =ROUND((1-gia_khuyen_mai[[#This Row],[% Giảm giá]]) * gia_khuyen_mai[[#This Row],[Giá gốc]], 0) -> 57456 | O52: =IFERROR(VLOOKUP(gia_khuyen_mai[[#This Row],[Mã hàng tặng]],'Giá gốc'!B:C,2,0),"") | Q52: =VLOOKUP(gia_khuyen_mai[[#This Row],[Mã sản phẩm]],product[[Mã sản phẩm]:[DS - ĐV]],3,0) -> Food Đức Việt
A53: =ROW()-1 -> 52 | B53: Mã mới | C53: Winmart | D53: Toàn quốc | E53: 09/04/2026 | F53: 13/05/2026 | G53: 8935101607976 | H53: =VLOOKUP(gia_khuyen_mai[[#This Row],[Barcode]],'Giá gốc'!$A:$B,2,0) -> 2145682 | I53: =VLOOKUP(gia_khuyen_mai[[#This Row],[Mã sản phẩm]],'Giá gốc'!$B:$C,2,0) -> O'Food - Xúc xích xốt Spaghetti 64g | J53: =VLOOKUP(gia_khuyen_mai[[#This Row],[Mã sản phẩm]],'Giá gốc'!B:D,3,0) -> 8837 | L53: =ROUND((1-gia_khuyen_mai[[#This Row],[% Giảm giá]]) * gia_khuyen_mai[[#This Row],[Giá gốc]], 0) -> 8837 | M53: Mua 1 tặng 1 | N53: =VLOOKUP(gia_khuyen_mai[[#This Row],[Barcode]],'Giá gốc'!$A:$B,2,0) -> 2145682 | O53: =IFERROR(VLOOKUP(gia_khuyen_mai[[#This Row],[Mã hàng tặng]],'Giá gốc'!B:C,2,0),"") -> O'Food - Xúc xích xốt Spaghetti 64g | Q53: =VLOOKUP(gia_khuyen_mai[[#This Row],[Mã sản phẩm]],product[[Mã sản phẩm]:[DS - ĐV]],3,0) -> Food Đức Việt
A54: =ROW()-1 -> 53 | B54: Mã mới | C54: Winmart | D54: Toàn quốc | E54: 09/04/2026 | F54: 13/05/2026 | G54: 8935101607990 | H54: =VLOOKUP(gia_khuyen_mai[[#This Row],[Barcode]],'Giá gốc'!$A:$B,2,0) -> 2145684 | I54: =VLOOKUP(gia_khuyen_mai[[#This Row],[Mã sản phẩm]],'Giá gốc'!$B:$C,2,0) -> O'Food - Xúc xích xốt Tokpokki vị phô mai Hàn Quốc 64g | J54: =VLOOKUP(gia_khuyen_mai[[#This Row],[Mã sản phẩm]],'Giá gốc'!B:D,3,0) -> 8837 | L54: =ROUND((1-gia_khuyen_mai[[#This Row],[% Giảm giá]]) * gia_khuyen_mai[[#This Row],[Giá gốc]], 0) -> 8837 | M54: Mua 1 tặng 1 | N54: =VLOOKUP(gia_khuyen_mai[[#This Row],[Barcode]],'Giá gốc'!$A:$B,2,0) -> 2145684 | O54: =IFERROR(VLOOKUP(gia_khuyen_mai[[#This Row],[Mã hàng tặng]],'Giá gốc'!B:C,2,0),"") -> O'Food - Xúc xích xốt Tokpokki vị phô mai Hàn Quốc 64g | Q54: =VLOOKUP(gia_khuyen_mai[[#This Row],[Mã sản phẩm]],product[[Mã sản phẩm]:[DS - ĐV]],3,0) -> Food Đức Việt
A55: =ROW()-1 -> 54 | B55: Mã mới | C55: Winmart | D55: Toàn quốc | E55: 09/04/2026 | F55: 13/05/2026 | G55: 8935101608492 | H55: =VLOOKUP(gia_khuyen_mai[[#This Row],[Barcode]],'Giá gốc'!$A:$B,2,0) -> 2149794 | I55: =VLOOKUP(gia_khuyen_mai[[#This Row],[Mã sản phẩm]],'Giá gốc'!$B:$C,2,0) -> Xúc xích Romas Light 500g | J55: =VLOOKUP(gia_khuyen_mai[[#This Row],[Mã sản phẩm]],'Giá gốc'!B:D,3,0) -> 44000 | L55: =ROUND((1-gia_khuyen_mai[[#This Row],[% Giảm giá]]) * gia_khuyen_mai[[#This Row],[Giá gốc]], 0) -> 44000 | M55: Mua 1 tặng 1 | N55: 2145740 | O55: =IFERROR(VLOOKUP(gia_khuyen_mai[[#This Row],[Mã hàng tặng]],'Giá gốc'!B:C,2,0),"") -> Xúc xích phô mai Cheesy 70g * 30EA | Q55: =VLOOKUP(gia_khuyen_mai[[#This Row],[Mã sản phẩm]],product[[Mã sản phẩm]:[DS - ĐV]],3,0) -> Food Đức Việt
A56: =ROW()-1 -> 55 | B56: Mã mới | C56: Win+ | D56: Toàn quốc | E56: 11/05/2026 | F56: 09/06/2026 | G56: 8935101608515 | H56: =VLOOKUP(gia_khuyen_mai[[#This Row],[Barcode]],'Giá gốc'!$A:$B,2,0) -> 2151032 | I56: =VLOOKUP(gia_khuyen_mai[[#This Row],[Mã sản phẩm]],'Giá gốc'!$B:$C,2,0) -> Jongga Kim chi Củ cải 450g | J56: =VLOOKUP(gia_khuyen_mai[[#This Row],[Mã sản phẩm]],'Giá gốc'!B:D,3,0) -> 42000 | L56: =ROUND((1-gia_khuyen_mai[[#This Row],[% Giảm giá]]) * gia_khuyen_mai[[#This Row],[Giá gốc]], 0) -> 42000 | M56: Mua 1 tặng 1 | N56: =VLOOKUP(gia_khuyen_mai[[#This Row],[Barcode]],'Giá gốc'!$A:$B,2,0) -> 2151032 | O56: =IFERROR(VLOOKUP(gia_khuyen_mai[[#This Row],[Mã hàng tặng]],'Giá gốc'!B:C,2,0),"") -> Jongga Kim chi Củ cải 450g | Q56: =VLOOKUP(gia_khuyen_mai[[#This Row],[Mã sản phẩm]],product[[Mã sản phẩm]:[DS - ĐV]],3,0) -> Food Đức Việt
A57: =ROW()-1 -> 56 | B57: Mã mới | C57: Win+ | D57: Toàn quốc | E57: 27/05/2026 | F57: 24/06/2026 | G57: 8935101608522 | H57: =VLOOKUP(gia_khuyen_mai[[#This Row],[Barcode]],'Giá gốc'!$A:$B,2,0) -> 2151140 | I57: =VLOOKUP(gia_khuyen_mai[[#This Row],[Mã sản phẩm]],'Giá gốc'!$B:$C,2,0) -> Jongga Kim chi Củ cải 150g | J57: =VLOOKUP(gia_khuyen_mai[[#This Row],[Mã sản phẩm]],'Giá gốc'!B:D,3,0) -> 16500 | K57: 0.33 | L57: =ROUND((1-gia_khuyen_mai[[#This Row],[% Giảm giá]]) * gia_khuyen_mai[[#This Row],[Giá gốc]], 0) -> 11055 | O57: =IFERROR(VLOOKUP(gia_khuyen_mai[[#This Row],[Mã hàng tặng]],'Giá gốc'!B:C,2,0),"") | Q57: =VLOOKUP(gia_khuyen_mai[[#This Row],[Mã sản phẩm]],product[[Mã sản phẩm]:[DS - ĐV]],3,0) -> Food Đức Việt
...

Sheet Thông tin điểm giao
A1: Mã điểm giao | B1: Hệ thống | C1: Tên điểm giao | D1: Địa chỉ điểm giao | E1: Mã khách hàng | F1: Tên khách hàng | G1: Chi nhánh | H1: Nhóm hàng | I1: Mã kho
A2: 5858 | B2: Win+ | C2: #N/A | D2: Số nhà 297, Cụm 2, Xã Thọ Xuân, Huyện Đan Phượng, TP. Hà Nội Việt Nam | E2: 73002016 | F2: =VLOOKUP(Table8[[#This Row],[Mã khách hàng]],code_khach_hang[],2,0) -> CHI NHÁNH HẢI DƯƠNG - CÔNG TY CỔ PHẦN DỊCH VỤ THƯƠNG MẠI TỔNG HỢP WINCOMMERCE | G2: =VLOOKUP(Table8[[#This Row],[Mã khách hàng]],code_khach_hang[],3,0) -> Miền Bắc đặc biệt 3 | H2: =VLOOKUP(Table8[[#This Row],[Mã khách hàng]],'Khách hàng'!A:D,4,0) -> Food Đức Việt | I2: =VLOOKUP(Table8[[#This Row],[Mã khách hàng]],'Khách hàng'!A:E,5,0) -> HN0040
A3: 6337 | B3: Win+ | C3: WM+ BNH 12-14 Tân Dân | D3: Tầng L1, TTTM Vincom Plaza Bắc Giang thuộc dự án đầu tư xây dựng nhà ở thương mại, số 41 đường Ngô Gia Tự, phường Bắc Giang, Tỉnh Bắc Ninh Việt Nam | E3: 73002010 | F3: =VLOOKUP(Table8[[#This Row],[Mã khách hàng]],code_khach_hang[],2,0) -> CHI NHÁNH BẮC NINH - CÔNG TY CỔ PHẦN DỊCH VỤ THƯƠNG MẠI TỔNG HỢP WINCOMMERCE | G3: =VLOOKUP(Table8[[#This Row],[Mã khách hàng]],code_khach_hang[],3,0) -> Miền Bắc đặc biệt 2 | H3: =VLOOKUP(Table8[[#This Row],[Mã khách hàng]],'Khách hàng'!A:D,4,0) -> Food Đức Việt | I3: =VLOOKUP(Table8[[#This Row],[Mã khách hàng]],'Khách hàng'!A:E,5,0) -> HN0040
A4: 4238 | B4: Win+ | C4: WM+ BNH Giang Liễu | D4: Số 531-533 Phố Đồi Ngô, Xã Lục Nam, T. Bắc Ninh Việt Nam | E4: 73002010 | F4: =VLOOKUP(Table8[[#This Row],[Mã khách hàng]],code_khach_hang[],2,0) -> CHI NHÁNH BẮC NINH - CÔNG TY CỔ PHẦN DỊCH VỤ THƯƠNG MẠI TỔNG HỢP WINCOMMERCE | G4: =VLOOKUP(Table8[[#This Row],[Mã khách hàng]],code_khach_hang[],3,0) -> Miền Bắc đặc biệt 2 | H4: =VLOOKUP(Table8[[#This Row],[Mã khách hàng]],'Khách hàng'!A:D,4,0) -> Food Đức Việt | I4: =VLOOKUP(Table8[[#This Row],[Mã khách hàng]],'Khách hàng'!A:E,5,0) -> HN0040
A5: 5871 | B5: Win+ | C5: WM+ BNH Khu 1 Phố Mới | D5: Số 101–103, Thôn Đội Cấn, Xã Vĩnh Tường, Tỉnh Phú Thọ T. Phú Thọ Việt Nam | E5: 73002010 | F5: =VLOOKUP(Table8[[#This Row],[Mã khách hàng]],code_khach_hang[],2,0) -> CHI NHÁNH BẮC NINH - CÔNG TY CỔ PHẦN DỊCH VỤ THƯƠNG MẠI TỔNG HỢP WINCOMMERCE | G5: =VLOOKUP(Table8[[#This Row],[Mã khách hàng]],code_khach_hang[],3,0) -> Miền Bắc đặc biệt 2 | H5: =VLOOKUP(Table8[[#This Row],[Mã khách hàng]],'Khách hàng'!A:D,4,0) -> Food Đức Việt | I5: =VLOOKUP(Table8[[#This Row],[Mã khách hàng]],'Khách hàng'!A:E,5,0) -> HN0040
A6: 6149 | B6: Win+ | C6: WM+ BNH Mao Dộc, Quế Võ | D6: Tòa nhà CT1A- CT1B Khu đô thị Xa la-, Quận Hà Đông, TP. Hà Nội Việt Nam | E6: 73002010 | F6: =VLOOKUP(Table8[[#This Row],[Mã khách hàng]],code_khach_hang[],2,0) -> CHI NHÁNH BẮC NINH - CÔNG TY CỔ PHẦN DỊCH VỤ THƯƠNG MẠI TỔNG HỢP WINCOMMERCE | G6: =VLOOKUP(Table8[[#This Row],[Mã khách hàng]],code_khach_hang[],3,0) -> Miền Bắc đặc biệt 2 | H6: =VLOOKUP(Table8[[#This Row],[Mã khách hàng]],'Khách hàng'!A:D,4,0) -> Food Đức Việt | I6: =VLOOKUP(Table8[[#This Row],[Mã khách hàng]],'Khách hàng'!A:E,5,0) -> HN0040
A7: 5985 | B7: Win+ | C7: WM+ BNH 380 - 382 Âu Cơ | D7: Tổ hợp nhà ở 28 tầng, làng Quốc tế, Thăng Long, P. Dịch Vọng, Quận Cầu Giấy, TP. Hà Nội Việt Nam | E7: 73002010 | F7: =VLOOKUP(Table8[[#This Row],[Mã khách hàng]],code_khach_hang[],2,0) -> CHI NHÁNH BẮC NINH - CÔNG TY CỔ PHẦN DỊCH VỤ THƯƠNG MẠI TỔNG HỢP WINCOMMERCE | G7: =VLOOKUP(Table8[[#This Row],[Mã khách hàng]],code_khach_hang[],3,0) -> Miền Bắc đặc biệt 2 | H7: =VLOOKUP(Table8[[#This Row],[Mã khách hàng]],'Khách hàng'!A:D,4,0) -> Food Đức Việt | I7: =VLOOKUP(Table8[[#This Row],[Mã khách hàng]],'Khách hàng'!A:E,5,0) -> HN0040
A8: 6263 | B8: Win+ | C8: WM+ BNH Khương Tự, Thuận Thành | D8: Số 72A đường Nguyễn Trãi - P., Thượng Đình, Quận Thanh Xuân, TP. Hà Nội Việt Nam | E8: 73002010 | F8: =VLOOKUP(Table8[[#This Row],[Mã khách hàng]],code_khach_hang[],2,0) -> CHI NHÁNH BẮC NINH - CÔNG TY CỔ PHẦN DỊCH VỤ THƯƠNG MẠI TỔNG HỢP WINCOMMERCE | G8: =VLOOKUP(Table8[[#This Row],[Mã khách hàng]],code_khach_hang[],3,0) -> Miền Bắc đặc biệt 2 | H8: =VLOOKUP(Table8[[#This Row],[Mã khách hàng]],'Khách hàng'!A:D,4,0) -> Food Đức Việt | I8: =VLOOKUP(Table8[[#This Row],[Mã khách hàng]],'Khách hàng'!A:E,5,0) -> HN0040
A9: 6386 | B9: Win+ | C9: WM+ BNH Ấp Đông Côi, TT Hồ | D9: TTTM Ocean Mall Trung Hòa - Đường, Hoàng Đạo Thúy, Quận Cầu Giấy, TP. Hà Nội Việt Nam | E9: 73002010 | F9: =VLOOKUP(Table8[[#This Row],[Mã khách hàng]],code_khach_hang[],2,0) -> CHI NHÁNH BẮC NINH - CÔNG TY CỔ PHẦN DỊCH VỤ THƯƠNG MẠI TỔNG HỢP WINCOMMERCE | G9: =VLOOKUP(Table8[[#This Row],[Mã khách hàng]],code_khach_hang[],3,0) -> Miền Bắc đặc biệt 2 | H9: =VLOOKUP(Table8[[#This Row],[Mã khách hàng]],'Khách hàng'!A:D,4,0) -> Food Đức Việt | I9: =VLOOKUP(Table8[[#This Row],[Mã khách hàng]],'Khách hàng'!A:E,5,0) -> HN0040
A10: 6433 | B10: Win+ | C10: WM+ BNH Mão Điền, Thuận Thành | D10: B1-C55 Khu đô thị Times City, 458 Minh Khai , P. Minh Khai, , Quận Hai Bà Trưng , TP. Hà Nội, Việt Nam | E10: 73002010 | F10: =VLOOKUP(Table8[[#This Row],[Mã khách hàng]],code_khach_hang[],2,0) -> CHI NHÁNH BẮC NINH - CÔNG TY CỔ PHẦN DỊCH VỤ THƯƠNG MẠI TỔNG HỢP WINCOMMERCE | G10: =VLOOKUP(Table8[[#This Row],[Mã khách hàng]],code_khach_hang[],3,0) -> Miền Bắc đặc biệt 2 | H10: =VLOOKUP(Table8[[#This Row],[Mã khách hàng]],'Khách hàng'!A:D,4,0) -> Food Đức Việt | I10: =VLOOKUP(Table8[[#This Row],[Mã khách hàng]],'Khách hàng'!A:E,5,0) -> HN0040
A11: 6622 | B11: Win+ | C11: WM+ BNH Đông Ngoại, Thuận Thành | D11: Tầng 1, TTTM Vincom Center, 191 Bà, Triệu, P. Lê Đại Hành, Quận Hai Bà Trưng, TP. Hà Nội Việt Nam | E11: 73002010 | F11: =VLOOKUP(Table8[[#This Row],[Mã khách hàng]],code_khach_hang[],2,0) -> CHI NHÁNH BẮC NINH - CÔNG TY CỔ PHẦN DỊCH VỤ THƯƠNG MẠI TỔNG HỢP WINCOMMERCE | G11: =VLOOKUP(Table8[[#This Row],[Mã khách hàng]],code_khach_hang[],3,0) -> Miền Bắc đặc biệt 2 | H11: =VLOOKUP(Table8[[#This Row],[Mã khách hàng]],'Khách hàng'!A:D,4,0) -> Food Đức Việt | I11: =VLOOKUP(Table8[[#This Row],[Mã khách hàng]],'Khách hàng'!A:E,5,0) -> HN0040
A12: 5128 | B12: Win+ | C12: WM+ BNH Số 74 Đường Nguyễn Đăng Đạo | D12: TTTM Vincom center Long Biên , Quận Long Biên , TP. Hà Nội, Việt Nam | E12: 73002010 | F12: =VLOOKUP(Table8[[#This Row],[Mã khách hàng]],code_khach_hang[],2,0) -> CHI NHÁNH BẮC NINH - CÔNG TY CỔ PHẦN DỊCH VỤ THƯƠNG MẠI TỔNG HỢP WINCOMMERCE | G12: =VLOOKUP(Table8[[#This Row],[Mã khách hàng]],code_khach_hang[],3,0) -> Miền Bắc đặc biệt 2 | H12: =VLOOKUP(Table8[[#This Row],[Mã khách hàng]],'Khách hàng'!A:D,4,0) -> Food Đức Việt | I12: =VLOOKUP(Table8[[#This Row],[Mã khách hàng]],'Khách hàng'!A:E,5,0) -> HN0040
A13: 5226 | B13: Win+ | C13: WM+ BNH Thôn Đại Thượng | D13: Tầng 1 nhà CT7A, khu đô thị mới văn, quán, Yên Phúc, P. Phúc La, Quận Hà Đông, TP. Hà Nội Việt Nam | E13: 73002010 | F13: =VLOOKUP(Table8[[#This Row],[Mã khách hàng]],code_khach_hang[],2,0) -> CHI NHÁNH BẮC NINH - CÔNG TY CỔ PHẦN DỊCH VỤ THƯƠNG MẠI TỔNG HỢP WINCOMMERCE | G13: =VLOOKUP(Table8[[#This Row],[Mã khách hàng]],code_khach_hang[],3,0) -> Miền Bắc đặc biệt 2 | H13: =VLOOKUP(Table8[[#This Row],[Mã khách hàng]],'Khách hàng'!A:D,4,0) -> Food Đức Việt | I13: =VLOOKUP(Table8[[#This Row],[Mã khách hàng]],'Khách hàng'!A:E,5,0) -> HN0040
A14: 5433 | B14: Win+ | C14: WM+ BNH Thôn Dương Húc | D14: 54A Nguyễn Chí Thanh, Quận Đống Đa, TP. Hà Nội Việt Nam | E14: 73002010 | F14: =VLOOKUP(Table8[[#This Row],[Mã khách hàng]],code_khach_hang[],2,0) -> CHI NHÁNH BẮC NINH - CÔNG TY CỔ PHẦN DỊCH VỤ THƯƠNG MẠI TỔNG HỢP WINCOMMERCE | G14: =VLOOKUP(Table8[[#This Row],[Mã khách hàng]],code_khach_hang[],3,0) -> Miền Bắc đặc biệt 2 | H14: =VLOOKUP(Table8[[#This Row],[Mã khách hàng]],'Khách hàng'!A:D,4,0) -> Food Đức Việt | I14: =VLOOKUP(Table8[[#This Row],[Mã khách hàng]],'Khách hàng'!A:E,5,0) -> HN0040
... A107: 5885 | B107: Win+ | C107: WM+ QNH 221 Nguyễn Bình | D107: 138 Phú Diễn, P. Phú Diễn, Quận, Quận Bắc Từ Liêm, TP. Hà Nội Việt Nam | E107: 73001998 | F107: =VLOOKUP(Table8[[#This Row],[Mã khách hàng]],code_khach_hang[],2,0) -> CHI NHÁNH QUẢNG NINH - CÔNG TY CỔ PHẦN DỊCH VỤ THƯƠNG MẠI TỔNG HỢP WINCOMMERCE | G107: =VLOOKUP(Table8[[#This Row],[Mã khách hàng]],code_khach_hang[],3,0) -> Miền Bắc đặc biệt 3 | H107: =VLOOKUP(Table8[[#This Row],[Mã khách hàng]],'Khách hàng'!A:D,4,0) -> Food Đức Việt | I107: =VLOOKUP(Table8[[#This Row],[Mã khách hàng]],'Khách hàng'!A:E,5,0) -> HN0040
A108: 5933 | B108: Win+ | C108: #N/A | D108: Số 17A Hàn Thuyên, Tổ 2, Phường Phạm, m Đình Hổ, Quận Hai Bà Trưng, TP. Hà Nội Việt Nam | E108: 73001998 | F108: =VLOOKUP(Table8[[#This Row],[Mã khách hàng]],code_khach_hang[],2,0) -> CHI NHÁNH QUẢNG NINH - CÔNG TY CỔ PHẦN DỊCH VỤ THƯƠNG MẠI TỔNG HỢP WINCOMMERCE | G108: =VLOOKUP(Table8[[#This Row],[Mã khách hàng]],code_khach_hang[],3,0) -> Miền Bắc đặc biệt 3 | H108: =VLOOKUP(Table8[[#This Row],[Mã khách hàng]],'Khách hàng'!A:D,4,0) -> Food Đức Việt | I108: =VLOOKUP(Table8[[#This Row],[Mã khách hàng]],'Khách hàng'!A:E,5,0) -> HN0040
A109: 6023 | B109: Win+ | C109: WM+ QNH Kim Sơn, Đông Triều | D109: Số 47 Phó Đức Chính, Phường Trúc Bạch, Quận Ba Đình, TP. Hà Nội Việt Nam | E109: 73001998 | F109: =VLOOKUP(Table8[[#This Row],[Mã khách hàng]],code_khach_hang[],2,0) -> CHI NHÁNH QUẢNG NINH - CÔNG TY CỔ PHẦN DỊCH VỤ THƯƠNG MẠI TỔNG HỢP WINCOMMERCE | G109: =VLOOKUP(Table8[[#This Row],[Mã khách hàng]],code_khach_hang[],3,0) -> Miền Bắc đặc biệt 3 | H109: =VLOOKUP(Table8[[#This Row],[Mã khách hàng]],'Khách hàng'!A:D,4,0) -> Food Đức Việt | I109: =VLOOKUP(Table8[[#This Row],[Mã khách hàng]],'Khách hàng'!A:E,5,0) -> HN0040
A110: 6130 | B110: Win+ | C110: WM+ QNH 708 Khu Mễ Xá 2 | D110: Căn 22 Lô 1 khu Lạc Trung, Phường, Vĩnh Tuy, Quận Hai Bà Trưng, TP. Hà Nội Việt Nam | E110: 73001998 | F110: =VLOOKUP(Table8[[#This Row],[Mã khách hàng]],code_khach_hang[],2,0) -> CHI NHÁNH QUẢNG NINH - CÔNG TY CỔ PHẦN DỊCH VỤ THƯƠNG MẠI TỔNG HỢP WINCOMMERCE | G110: =VLOOKUP(Table8[[#This Row],[Mã khách hàng]],code_khach_hang[],3,0) -> Miền Bắc đặc biệt 3 | H110: =VLOOKUP(Table8[[#This Row],[Mã khách hàng]],'Khách hàng'!A:D,4,0) -> Food Đức Việt | I110: =VLOOKUP(Table8[[#This Row],[Mã khách hàng]],'Khách hàng'!A:E,5,0) -> HN0040
A111: 6681 | B111: Win+ | C111: #N/A | D111: Số 41, Tổ 5, Phố Trung Kính , Phường Trung Hòa, Quận Cầu Giấy , TP. Hà Nội, Việt Nam | E111: 73001998 | F111: =VLOOKUP(Table8[[#This Row],[Mã khách hàng]],code_khach_hang[],2,0) -> CHI NHÁNH QUẢNG NINH - CÔNG TY CỔ PHẦN DỊCH VỤ THƯƠNG MẠI TỔNG HỢP WINCOMMERCE | G111: =VLOOKUP(Table8[[#This Row],[Mã khách hàng]],code_khach_hang[],3,0) -> Miền Bắc đặc biệt 3 | H111: =VLOOKUP(Table8[[#This Row],[Mã khách hàng]],'Khách hàng'!A:D,4,0) -> Food Đức Việt | I111: =VLOOKUP(Table8[[#This Row],[Mã khách hàng]],'Khách hàng'!A:E,5,0) -> HN0040
A112: 6708 | B112: Win+ | C112: WM+ QNH 103 Hoàng Hoa Thám | D112: Số 210 Bis phố Đội Cấn, Phường Đội, Cấn, Quận Ba Đình, TP. Hà Nội Việt Nam | E112: 73001998 | F112: =VLOOKUP(Table8[[#This Row],[Mã khách hàng]],code_khach_hang[],2,0) -> CHI NHÁNH QUẢNG NINH - CÔNG TY CỔ PHẦN DỊCH VỤ THƯƠNG MẠI TỔNG HỢP WINCOMMERCE | G112: =VLOOKUP(Table8[[#This Row],[Mã khách hàng]],code_khach_hang[],3,0) -> Miền Bắc đặc biệt 3 | H112: =VLOOKUP(Table8[[#This Row],[Mã khách hàng]],'Khách hàng'!A:D,4,0) -> Food Đức Việt | I112: =VLOOKUP(Table8[[#This Row],[Mã khách hàng]],'Khách hàng'!A:E,5,0) -> HN0040
A113: 5958 | B113: Win+ | C113: WM+ QNH Khu 7, Nam Hòa | D113: Số 50 đường Nguyễn Hoàng Tôn, phường Xuân La, Quận Tây Hồ, TP. Hà Nội Việt Nam | E113: 73001998 | F113: =VLOOKUP(Table8[[#This Row],[Mã khách hàng]],code_khach_hang[],2,0) -> CHI NHÁNH QUẢNG NINH - CÔNG TY CỔ PHẦN DỊCH VỤ THƯƠNG MẠI TỔNG HỢP WINCOMMERCE | G113: =VLOOKUP(Table8[[#This Row],[Mã khách hàng]],code_khach_hang[],3,0) -> Miền Bắc đặc biệt 3 | H113: =VLOOKUP(Table8[[#This Row],[Mã khách hàng]],'Khách hàng'!A:D,4,0) -> Food Đức Việt | I113: =VLOOKUP(Table8[[#This Row],[Mã khách hàng]],'Khách hàng'!A:E,5,0) -> HN0040
A114: 6787 | B114: Win+ | C114: WM+ QNH 998 Khu Đường Ngang | D114: Số 55 Thụy Khuê, Phường Thụy Khuê, Quận Tây Hồ, TP. Hà Nội Việt Nam | E114: 73001998 | F114: =VLOOKUP(Table8[[#This Row],[Mã khách hàng]],code_khach_hang[],2,0) -> CHI NHÁNH QUẢNG NINH - CÔNG TY CỔ PHẦN DỊCH VỤ THƯƠNG MẠI TỔNG HỢP WINCOMMERCE | G114: =VLOOKUP(Table8[[#This Row],[Mã khách hàng]],code_khach_hang[],3,0) -> Miền Bắc đặc biệt 3 | H114: =VLOOKUP(Table8[[#This Row],[Mã khách hàng]],'Khách hàng'!A:D,4,0) -> Food Đức Việt | I114: =VLOOKUP(Table8[[#This Row],[Mã khách hàng]],'Khách hàng'!A:E,5,0) -> HN0040
A115: 6949 | B115: Win+ | C115: WM+ QNH 225 Lê Lợi | D115: Số 35B, đường Xuân La, Phường Xuân, La, Quận Tây Hồ, TP. Hà Nội Việt Nam | E115: 73001998 | F115: =VLOOKUP(Table8[[#This Row],[Mã khách hàng]],code_khach_hang[],2,0) -> CHI NHÁNH QUẢNG NINH - CÔNG TY CỔ PHẦN DỊCH VỤ THƯƠNG MẠI TỔNG HỢP WINCOMMERCE | G115: =VLOOKUP(Table8[[#This Row],[Mã khách hàng]],code_khach_hang[],3,0) -> Miền Bắc đặc biệt 3 | H115: =VLOOKUP(Table8[[#This Row],[Mã khách hàng]],'Khách hàng'!A:D,4,0) -> Food Đức Việt | I115: =VLOOKUP(Table8[[#This Row],[Mã khách hàng]],'Khách hàng'!A:E,5,0) -> HN0040
A116: 6899 | B116: Win+ | C116: WM+ QNH Tiền An, Quảng Yên | D116: Số 16 Võ Văn Dũng, Phường Ô Chợ, Dừa, Quận Đống Đa, TP. Hà Nội Việt Nam | E116: 73001998 | F116: =VLOOKUP(Table8[[#This Row],[Mã khách hàng]],code_khach_hang[],2,0) -> CHI NHÁNH QUẢNG NINH - CÔNG TY CỔ PHẦN DỊCH VỤ THƯƠNG MẠI TỔNG HỢP WINCOMMERCE | G116: =VLOOKUP(Table8[[#This Row],[Mã khách hàng]],code_khach_hang[],3,0) -> Miền Bắc đặc biệt 3 | H116: =VLOOKUP(Table8[[#This Row],[Mã khách hàng]],'Khách hàng'!A:D,4,0) -> Food Đức Việt | I116: =VLOOKUP(Table8[[#This Row],[Mã khách hàng]],'Khách hàng'!A:E,5,0) -> HN0040
A117: 6986 | B117: Win+ | C117: WM+ QNH 161 Lê Lợi | D117: Số 3, dãy N1, Học viện Chính trị qu, ân sự, Phường Trung Văn, Quận Nam Từ Liêm, TP. Hà Nội Việt Nam | E117: 73001998 | F117: =VLOOKUP(Table8[[#This Row],[Mã khách hàng]],code_khach_hang[],2,0) -> CHI NHÁNH QUẢNG NINH - CÔNG TY CỔ PHẦN DỊCH VỤ THƯƠNG MẠI TỔNG HỢP WINCOMMERCE | G117: =VLOOKUP(Table8[[#This Row],[Mã khách hàng]],code_khach_hang[],3,0) -> Miền Bắc đặc biệt 3 | H117: =VLOOKUP(Table8[[#This Row],[Mã khách hàng]],'Khách hàng'!A:D,4,0) -> Food Đức Việt | I117: =VLOOKUP(Table8[[#This Row],[Mã khách hàng]],'Khách hàng'!A:E,5,0) -> HN0040
A118: 6576 | B118: Win+ | C118: WM+ QNH 268 Trần Khánh Dư | D118: Số 10 Ngõ 118 Nguyễn Khánh Toàn, ph, ường Quan Hoa, Quận Cầu Giấy, TP. Hà Nội Việt Nam | E118: 73001998 | F118: =VLOOKUP(Table8[[#This Row],[Mã khách hàng]],code_khach_hang[],2,0) -> CHI NHÁNH QUẢNG NINH - CÔNG TY CỔ PHẦN DỊCH VỤ THƯƠNG MẠI TỔNG HỢP WINCOMMERCE | G118: =VLOOKUP(Table8[[#This Row],[Mã khách hàng]],code_khach_hang[],3,0) -> Miền Bắc đặc biệt 3 | H118: =VLOOKUP(Table8[[#This Row],[Mã khách hàng]],'Khách hàng'!A:D,4,0) -> Food Đức Việt | I118: =VLOOKUP(Table8[[#This Row],[Mã khách hàng]],'Khách hàng'!A:E,5,0) -> HN0040
A119: 2AB5 | B119: Win+ | C119: WM+ QNH 189 Tổ 18, Khu 3 Trưng Vươn | D119: Số 57 Phố 8/3, Phường Quỳnh Mai, Qu, ận Hai Bà Trưng, TP. Hà Nội Việt Nam | E119: 73001998 | F119: =VLOOKUP(Table8[[#This Row],[Mã khách hàng]],code_khach_hang[],2,0) -> CHI NHÁNH QUẢNG NINH - CÔNG TY CỔ PHẦN DỊCH VỤ THƯƠNG MẠI TỔNG HỢP WINCOMMERCE | G119: =VLOOKUP(Table8[[#This Row],[Mã khách hàng]],code_khach_hang[],3,0) -> Miền Bắc đặc biệt 3 | H119: =VLOOKUP(Table8[[#This Row],[Mã khách hàng]],'Khách hàng'!A:D,4,0) -> Food Đức Việt | I119: =VLOOKUP(Table8[[#This Row],[Mã khách hàng]],'Khách hàng'!A:E,5,0) -> HN0040
A120: 2AL2 | B120: Win+ | C120: WM+ QNH 352 Trần Phú | D120: Số 133 Phố Thụy Khuê, Phường Thụy Khuê, Quận Tây Hồ, TP. Hà Nội Việt Nam | E120: 73001998 | F120: =VLOOKUP(Table8[[#This Row],[Mã khách hàng]],code_khach_hang[],2,0) -> CHI NHÁNH QUẢNG NINH - CÔNG TY CỔ PHẦN DỊCH VỤ THƯƠNG MẠI TỔNG HỢP WINCOMMERCE | G120: =VLOOKUP(Table8[[#This Row],[Mã khách hàng]],code_khach_hang[],3,0) -> Miền Bắc đặc biệt 3 | H120: =VLOOKUP(Table8[[#This Row],[Mã khách hàng]],'Khách hàng'!A:D,4,0) -> Food Đức Việt | I120: =VLOOKUP(Table8[[#This Row],[Mã khách hàng]],'Khách hàng'!A:E,5,0) -> HN0040
A121: 1647 | B121: Winmart | C121: WM VCP QNH Móng Cái | D121: Số 409 Bạch Mai, Phường Bạch Mai, Q, uận Hai Bà Trưng, TP. Hà Nội Việt Nam | E121: 73001998 | F121: =VLOOKUP(Table8[[#This Row],[Mã khách hàng]],code_khach_hang[],2,0) -> CHI NHÁNH QUẢNG NINH - CÔNG TY CỔ PHẦN DỊCH VỤ THƯƠNG MẠI TỔNG HỢP WINCOMMERCE | G121: =VLOOKUP(Table8[[#This Row],[Mã khách hàng]],code_khach_hang[],3,0) -> Miền Bắc đặc biệt 3 | H121: =VLOOKUP(Table8[[#This Row],[Mã khách hàng]],'Khách hàng'!A:D,4,0) -> Food Đức Việt | I121: =VLOOKUP(Table8[[#This Row],[Mã khách hàng]],'Khách hàng'!A:E,5,0) -> HN0040
A122: 1605 | B122: Winmart | C122: WM VC+ QNH Uông Bí | D122: Số 18B Nguyễn Biểu, Phường Quán Thánh, Quận Ba Đình, TP. Hà Nội Việt Nam | E122: 73001998 | F122: =VLOOKUP(Table8[[#This Row],[Mã khách hàng]],code_khach_hang[],2,0) -> CHI NHÁNH QUẢNG NINH - CÔNG TY CỔ PHẦN DỊCH VỤ THƯƠNG MẠI TỔNG HỢP WINCOMMERCE | G122: =VLOOKUP(Table8[[#This Row],[Mã khách hàng]],code_khach_hang[],3,0) -> Miền Bắc đặc biệt 3 | H122: =VLOOKUP(Table8[[#This Row],[Mã khách hàng]],'Khách hàng'!A:D,4,0) -> Food Đức Việt | I122: =VLOOKUP(Table8[[#This Row],[Mã khách hàng]],'Khách hàng'!A:E,5,0) -> HN0040
A123: 5401 | B123: Win+ | C123: WM+ HPG 309 Trường Sơn | D123: 102 Lê Thanh Nghị, Phường Bách K, hoa, Quận Hai Bà Trưng, TP. Hà Nội Việt Nam | E123: 73002017 | F123: =VLOOKUP(Table8[[#This Row],[Mã khách hàng]],code_khach_hang[],2,0) -> CHI NHÁNH HẢI PHÒNG - CÔNG TY CỔ PHẦN DỊCH VỤ THƯƠNG MẠI TỔNG HỢP WINCOMMERCE | G123: =VLOOKUP(Table8[[#This Row],[Mã khách hàng]],code_khach_hang[],3,0) -> Miền Bắc đặc biệt 3 | H123: =VLOOKUP(Table8[[#This Row],[Mã khách hàng]],'Khách hàng'!A:D,4,0) -> Food Đức Việt | I123: =VLOOKUP(Table8[[#This Row],[Mã khách hàng]],'Khách hàng'!A:E,5,0) -> HN0040
... A145: 3233 | B145: Win+ | C145: WM+ HPG 118 Hùng Vương | D145: 20 Ngô Thì Nhậm, P. Hà Cầu, Quận Hà Đông, TP. Hà Nội Việt Nam | E145: 73002017 | F145: =VLOOKUP(Table8[[#This Row],[Mã khách hàng]],code_khach_hang[],2,0) -> CHI NHÁNH HẢI PHÒNG - CÔNG TY CỔ PHẦN DỊCH VỤ THƯƠNG MẠI TỔNG HỢP WINCOMMERCE | G145: =VLOOKUP(Table8[[#This Row],[Mã khách hàng]],code_khach_hang[],3,0) -> Miền Bắc đặc biệt 3 | H145: =VLOOKUP(Table8[[#This Row],[Mã khách hàng]],'Khách hàng'!A:D,4,0) -> Food Đức Việt | I145: =VLOOKUP(Table8[[#This Row],[Mã khách hàng]],'Khách hàng'!A:E,5,0) -> HN0040
A146: 3031 | B146: Win+ | C146: #N/A | D146: 129 Pháo Đài Láng, P. Láng Thượng, Đống Đa, TP. Hà Nội Việt Nam | E146: 73002017 | F146: =VLOOKUP(Table8[[#This Row],[Mã khách hàng]],code_khach_hang[],2,0) -> CHI NHÁNH HẢI PHÒNG - CÔNG TY CỔ PHẦN DỊCH VỤ THƯƠNG MẠI TỔNG HỢP WINCOMMERCE | G146: =VLOOKUP(Table8[[#This Row],[Mã khách hàng]],code_khach_hang[],3,0) -> Miền Bắc đặc biệt 3 | H146: =VLOOKUP(Table8[[#This Row],[Mã khách hàng]],'Khách hàng'!A:D,4,0) -> Food Đức Việt | I146: =VLOOKUP(Table8[[#This Row],[Mã khách hàng]],'Khách hàng'!A:E,5,0) -> HN0040
A147: 3787 | B147: Win+ | C147: WM+ HPG Club House Imperia | D147: 166 Kim Hoa, P. Phương Liên, Đống Đa, TP. Hà Nội Việt Nam | E147: 73002017 | F147: =VLOOKUP(Table8[[#This Row],[Mã khách hàng]],code_khach_hang[],2,0) -> CHI NHÁNH HẢI PHÒNG - CÔNG TY CỔ PHẦN DỊCH VỤ THƯƠNG MẠI TỔNG HỢP WINCOMMERCE | G147: =VLOOKUP(Table8[[#This Row],[Mã khách hàng]],code_khach_hang[],3,0) -> Miền Bắc đặc biệt 3 | H147: =VLOOKUP(Table8[[#This Row],[Mã khách hàng]],'Khách hàng'!A:D,4,0) -> Food Đức Việt | I147: =VLOOKUP(Table8[[#This Row],[Mã khách hàng]],'Khách hàng'!A:E,5,0) -> HN0040
A148: 5092 | B148: Win+ | C148: WM+ HPG Số 46 Bãi Sậy-Trại Chuối | D148: 66 Đại Cồ Việt, P. Lê Đại Hành, Q., Quận Hai Bà Trưng, TP. Hà Nội Việt Nam | E148: 73002017 | F148: =VLOOKUP(Table8[[#This Row],[Mã khách hàng]],code_khach_hang[],2,0) -> CHI NHÁNH HẢI PHÒNG - CÔNG TY CỔ PHẦN DỊCH VỤ THƯƠNG MẠI TỔNG HỢP WINCOMMERCE | G148: =VLOOKUP(Table8[[#This Row],[Mã khách hàng]],code_khach_hang[],3,0) -> Miền Bắc đặc biệt 3 | H148: =VLOOKUP(Table8[[#This Row],[Mã khách hàng]],'Khách hàng'!A:D,4,0) -> Food Đức Việt | I148: =VLOOKUP(Table8[[#This Row],[Mã khách hàng]],'Khách hàng'!A:E,5,0) -> HN0040
A149: 5307 | B149: Win+ | C149: WM+ HPG BH 03-11 KĐT Xi Măng HP | D149: Ô 58 lô 6 tổ 44 Đền Lừ II, P.Hoàng, Văn Thụ, Q. Hoàng Mai, TP. Hà Nội Việt Nam | E149: 73002017 | F149: =VLOOKUP(Table8[[#This Row],[Mã khách hàng]],code_khach_hang[],2,0) -> CHI NHÁNH HẢI PHÒNG - CÔNG TY CỔ PHẦN DỊCH VỤ THƯƠNG MẠI TỔNG HỢP WINCOMMERCE | G149: =VLOOKUP(Table8[[#This Row],[Mã khách hàng]],code_khach_hang[],3,0) -> Miền Bắc đặc biệt 3 | H149: =VLOOKUP(Table8[[#This Row],[Mã khách hàng]],'Khách hàng'!A:D,4,0) -> Food Đức Việt | I149: =VLOOKUP(Table8[[#This Row],[Mã khách hàng]],'Khách hàng'!A:E,5,0) -> HN0040
A150: 6083 | B150: Win+ | C150: WM+ HPG 5/4 Quán Toan | D150: 121B Quan Hoa, P. Quan Hoa, Quận Cầu Giấy, TP. Hà Nội Việt Nam | E150: 73002017 | F150: =VLOOKUP(Table8[[#This Row],[Mã khách hàng]],code_khach_hang[],2,0) -> CHI NHÁNH HẢI PHÒNG - CÔNG TY CỔ PHẦN DỊCH VỤ THƯƠNG MẠI TỔNG HỢP WINCOMMERCE | G150: =VLOOKUP(Table8[[#This Row],[Mã khách hàng]],code_khach_hang[],3,0) -> Miền Bắc đặc biệt 3 | H150: =VLOOKUP(Table8[[#This Row],[Mã khách hàng]],'Khách hàng'!A:D,4,0) -> Food Đức Việt | I150: =VLOOKUP(Table8[[#This Row],[Mã khách hàng]],'Khách hàng'!A:E,5,0) -> HN0040
A151: 6362 | B151: Win+ | C151: WM+ HPG 42 Trương Văn Lực | D151: Số 1 Ngõ 12 Chính Kinh, Phường Nhân Chính, Quận Thanh Xuân, TP. Hà Nội Việt Nam | E151: 73002017 | F151: =VLOOKUP(Table8[[#This Row],[Mã khách hàng]],code_khach_hang[],2,0) -> CHI NHÁNH HẢI PHÒNG - CÔNG TY CỔ PHẦN DỊCH VỤ THƯƠNG MẠI TỔNG HỢP WINCOMMERCE | G151: =VLOOKUP(Table8[[#This Row],[Mã khách hàng]],code_khach_hang[],3,0) -> Miền Bắc đặc biệt 3 | H151: =VLOOKUP(Table8[[#This Row],[Mã khách hàng]],'Khách hàng'!A:D,4,0) -> Food Đức Việt | I151: =VLOOKUP(Table8[[#This Row],[Mã khách hàng]],'Khách hàng'!A:E,5,0) -> HN0040
A152: 2861 | B152: Win+ | C152: WM+ HPG 12 Lê Duẩn | D152: B15 Bồ Hỏa, Quận Hà Đông, TP. Hà Nội Việt Nam | E152: 73002017 | F152: =VLOOKUP(Table8[[#This Row],[Mã khách hàng]],code_khach_hang[],2,0) -> CHI NHÁNH HẢI PHÒNG - CÔNG TY CỔ PHẦN DỊCH VỤ THƯƠNG MẠI TỔNG HỢP WINCOMMERCE | G152: =VLOOKUP(Table8[[#This Row],[Mã khách hàng]],code_khach_hang[],3,0) -> Miền Bắc đặc biệt 3 | H152: =VLOOKUP(Table8[[#This Row],[Mã khách hàng]],'Khách hàng'!A:D,4,0) -> Food Đức Việt | I152: =VLOOKUP(Table8[[#This Row],[Mã khách hàng]],'Khách hàng'!A:E,5,0) -> HN0040
A153: 3606 | B153: Win+ | C153: WM+ HPG 80 Trường Chinh | D153: 668 Lạc Long Quân, Quận Tây Hồ, TP. Hà Nội Việt Nam | E153: 73002017 | F153: =VLOOKUP(Table8[[#This Row],[Mã khách hàng]],code_khach_hang[],2,0) -> CHI NHÁNH HẢI PHÒNG - CÔNG TY CỔ PHẦN DỊCH VỤ THƯƠNG MẠI TỔNG HỢP WINCOMMERCE | G153: =VLOOKUP(Table8[[#This Row],[Mã khách hàng]],code_khach_hang[],3,0) -> Miền Bắc đặc biệt 3 | H153: =VLOOKUP(Table8[[#This Row],[Mã khách hàng]],'Khách hàng'!A:D,4,0) -> Food Đức Việt | I153: =VLOOKUP(Table8[[#This Row],[Mã khách hàng]],'Khách hàng'!A:E,5,0) -> HN0040
...

Sheet Khách hàng
A1: Mã khách hàng | B1: Tên khách hàng | C1: Chi nhánh | D1: Nhóm hàng | E1: Mã kho
A2: 73002010 | B2: CHI NHÁNH BẮC NINH - CÔNG TY CỔ PHẦN DỊCH VỤ THƯƠNG MẠI TỔNG HỢP WINCOMMERCE | C2: Miền Bắc đặc biệt 2 | D2: Food Đức Việt | E2: HN0040
A3: 73002005 | B3: CHI NHÁNH VĨNH PHÚC - CÔNG TY CỔ PHẦN DỊCH VỤ THƯƠNG MẠI TỔNG HỢP WINCOMMERCE | C3: Miền Bắc đặc biệt 2 | D3: Food Đức Việt | E3: HN0040
A4: 73002776 | B4: CHI NHÁNH HÀ NỘI - CÔNG TY CỔ PHẦN DỊCH VỤ THƯƠNG MẠI TỔNG HỢP WINCOMMERCE | C4: Miền Bắc đặc biệt 2 | D4: Food Đức Việt | E4: HN0040
A5: 73002019 | B5: CHI NHÁNH HƯNG YÊN - CÔNG TY CỔ PHẦN DỊCH VỤ THƯƠNG MẠI TỔNG HỢP WINCOMMERCE | C5: Miền Bắc đặc biệt 1 | D5: Food Đức Việt | E5: HN0040
A6: 73002017 | B6: CHI NHÁNH HẢI PHÒNG - CÔNG TY CỔ PHẦN DỊCH VỤ THƯƠNG MẠI TỔNG HỢP WINCOMMERCE | C6: Miền Bắc đặc biệt 3 | D6: Food Đức Việt | E6: HN0040
A7: 73001997 | B7: CHI NHÁNH QUẢNG BÌNH - CÔNG TY CỔ PHẦN DỊCH VỤ THƯƠNG MẠI TỔNG HỢP WINCOMMERCE | C7: Miền Trung đặc biệt 1 | D7: Food Đức Việt | E7: HN0040
A8: 73002015 | B8: CHI NHÁNH HÀ TĨNH - CÔNG TY CỔ PHẦN DỊCH VỤ THƯƠNG MẠI TỔNG HỢP WINCOMMERCE | C8: Miền Trung đặc biệt 1 | D8: Food Đức Việt | E8: HN0040
A9: 73001994 | B9: CHI NHÁNH NGHỆ AN - CÔNG TY CỔ PHẦN DỊCH VỤ THƯƠNG MẠI TỔNG HỢP WINCOMMERCE | C9: Miền Trung đặc biệt 1 | D9: Food Đức Việt | E9: HN0040
A10: 73002000 | B10: CHI NHÁNH THÁI BÌNH - CÔNG TY CỔ PHẦN DỊCH VỤ THƯƠNG MẠI TỔNG HỢP WINCOMMERCE | C10: Miền Bắc đặc biệt 3 | D10: Food Đức Việt | E10: HN0040
A11: 73002008 | B11: CHI NHÁNH BẮC GIANG - CÔNG TY CỔ PHẦN DỊCH VỤ THƯƠNG MẠI TỔNG HỢP WINCOMMERCE | C11: Miền Bắc đặc biệt 2 | D11: Food Đức Việt | E11: HN0040
A12: 73002002 | B12: CHI NHÁNH THANH HÓA - CÔNG TY CỔ PHẦN DỊCH VỤ THƯƠNG MẠI TỔNG HỢP WINCOMMERCE | C12: Miền Trung đặc biệt 1 | D12: Food Đức Việt | E12: HN0040
... A50: 73002044 | B50: CHI NHÁNH PHÚ YÊN - CÔNG TY CỔ PHẦN DỊCH VỤ THƯƠNG MẠI TỔNG HỢP WINCOMMERCE | C50: Miền Trung đặc biệt 2 | D50: Food Đức Việt | E50: QNTV50

Sheet Cost Center
A1: Nhóm sản phẩm | B1: Chi nhánh | C1: Cost center | D1: Tên
A2: MSG | B2: Miền Bắc đặc biệt 1 | C2: B_77BDBM | D2: CN MB Đặc biệt 1 (MSG)
A3: Food Daesang | B3: Miền Bắc đặc biệt 1 | C3: B_78BDBF | D3: CN MB Đặc biệt 1(O'Food)
A4: Food Nhập Khẩu | B4: Miền Bắc đặc biệt 1 | C4: B_107BDB | D4: CN Miền bắc ĐB 1 ( Food NK)
A5: Food Đức Việt | B5: Miền Bắc đặc biệt 1 | C5: B_157DB1 | D5: CN MBDB1_hàng TM đức việt
A6: MSG | B6: Miền Bắc đặc biệt 2 | C6: B126BDBM | D6: CN MB Đặc biệt 2 (MSG)
A7: Food Daesang | B7: Miền Bắc đặc biệt 2 | C7: B127BDBF | D7: CN MB Đặc biệt 2 (O'Food)
A8: Food Nhập Khẩu | B8: Miền Bắc đặc biệt 2 | C8: B129BDBN | D8: CN Miền bắc ĐB 2 ( Food NK)
A9: Food Đức Việt | B9: Miền Bắc đặc biệt 2 | C9: B_156DB2 | D9: CN MBDB2_hàng TM đức việt
A10: MSG | B10: Miền Bắc đặc biệt 3 | C10: B156NB3M | D10: CN MN Đặc biệt 3 ( MSG)
A11: Food Daesang | B11: Miền Nam đặc biệt 3 | C11: B157NB3F | D11: CN MN Đặc biệt 3 (Food)
A12: Food Nhập Khẩu | B12: Miền Nam đặc biệt 3 | C12: B158NB3N | D12: CN MN Đặc biệt 3 ( Food Nk)
... A15: Food Đức Việt | B15: Miền Trung đặc biệt 1 | C15: B_163DB1 | D15: CN MTDB1_hàng TM đức việt

Sheet Data Validation
A1: Phạm vi | C1: Hệ thống | E1: Chương trình KM | G1: DS-DV | I1: MSG - DS - NK - ĐV | K1: Chi nhánh | M1: Mã kho | N1: Tên kho
A2: Toàn quốc | C2: Toàn bộ | E2: Mua 1 tặng 1 | G2: Food Đức Việt | I2: Food Đức Việt | K2: Miền Bắc đặc biệt 1 | M2: HN0040
A3: Miền Bắc | C3: Win+ | E3: Mua 2 tặng 1 | G3: Food Daesang | I3: Food Daesang | K3: Miền Bắc đặc biệt 2 | M3: HN-HD110
A4: Miền Nam | C4: Winmart | I4: MSG | K4: Miền Bắc đặc biệt 3 | M4: HNTG100
A5: Miền Trung | I5: Food Nhập Khẩu | K5: Miền Trung đặc biệt 1 | M5: HN-VH110
K6: Miền Trung đặc biệt 2 | M6: DNTG100
K7: Miền Nam đặc biệt 1 | M7: QNTV50
K8: Miền Nam đặc biệt 2
